#usda 1.0
(
    customLayerData = {
        string creator = "URDF USD Converter v0.1.2"
    }
    defaultPrim = "humanoid_urdf"
    doc = """Generated from Composed Stage of root layer C:\\Users\\jeong\\AppData\\Local\\Temp\\tmp7brmvyr4\\humanoid_urdf.usdc


Generated from Composed Stage of root layer C:\\Users\\jeong\\AppData\\Local\\Temp\\urdf_import_humanoid_urdf_sd66553_\\usdex_humanoid_urdf\\humanoid_urdf.usdc


Generated from Composed Stage of root layer C:\\Users\\jeong\\AppData\\Local\\Temp\\urdf_import_humanoid_urdf_sd66553_\\temp_humanoid_urdf\\humanoid_urdf.usd


Generated from Composed Stage of root layer D:\\making\\dynamixel\\train_arm\\humanoid_urdf_description\\humanoid_urdf_description\\urdf\\humanoid_urdf_1\\payloads\\base.usd
"""
    kilogramsPerUnit = 1
    metersPerUnit = 1
    upAxis = "Z"
)

over "humanoid_urdf"
{
    over "Geometry"
    {
        over "base_link" (
            prepend apiSchemas = ["PhysicsRigidBodyAPI", "PhysicsArticulationRootAPI", "NewtonArticulationRootAPI", "PhysicsMassAPI"]
        )
        {
            bool newton:selfCollisionEnabled = 0
            point3f physics:centerOfMass = (-0.005799008, -0.001942258, 0.33508903)
            float3 physics:diagonalInertia = (0.002884, 0.0031761038, 0.004033896)
            float physics:mass = 0.6659241
            quatf physics:principalAxes = (-0.45542198, 0.5409166, 0.5409166, 0.45542198)

            over "rshd_pitch_1" (
                prepend apiSchemas = ["PhysicsRigidBodyAPI", "PhysicsMassAPI"]
            )
            {
                point3f physics:centerOfMass = (-2.260135e-7, -0.012912923, -1.5564211e-7)
                float3 physics:diagonalInertia = (0.000003, 0.000006, 0.000007)
                float physics:mass = 0.015711742
                quatf physics:principalAxes = (1, 0, 0, 0)

                over "rshd_2xl_1" (
                    prepend apiSchemas = ["PhysicsRigidBodyAPI", "PhysicsMassAPI"]
                )
                {
                    point3f physics:centerOfMass = (0.018505184, -0.004985075, 0.012290301)
                    float3 physics:diagonalInertia = (0.000020565261, 0.00002323706, 0.000028197677)
                    float physics:mass = 0.08457536
                    quatf physics:principalAxes = (0.68373984, -0.075667135, 0.69340324, 0.21439749)

                    over "rshd_yaw_1" (
                        prepend apiSchemas = ["PhysicsRigidBodyAPI", "PhysicsMassAPI"]
                    )
                    {
                        point3f physics:centerOfMass = (-2.217948e-7, -0.020294169, -1.2753647e-7)
                        float3 physics:diagonalInertia = (0.000004, 0.000005, 0.000007)
                        float physics:mass = 0.016893674
                        quatf physics:principalAxes = (0.70710677, 0, 0.70710677, 0)

                        over "relbow_1" (
                            prepend apiSchemas = ["PhysicsRigidBodyAPI", "PhysicsMassAPI"]
                        )
                        {
                            point3f physics:centerOfMass = (-2.2604826e-7, -0.02860449, 0.018959701)
                            float3 physics:diagonalInertia = (0.00003190928, 0.00007609072, 0.000098)
                            float physics:mass = 0.0883854
                            quatf physics:principalAxes = (-0.5112031, 0.48854005, 0.5112031, 0.48854005)

                            over "rwrist_1" (
                                prepend apiSchemas = ["PhysicsRigidBodyAPI", "PhysicsMassAPI"]
                            )
                            {
                                point3f physics:centerOfMass = (0.00075738167, 0.011419835, -0.026135357)
                                float3 physics:diagonalInertia = (0.000023837722, 0.000024, 0.000030162279)
                                float physics:mass = 0.08793325
                                quatf physics:principalAxes = (0.64800376, 0, 0.76163715, 0)

                                over "rgripper_1" (
                                    prepend apiSchemas = ["PhysicsRigidBodyAPI", "PhysicsMassAPI"]
                                )
                                {
                                    point3f physics:centerOfMass = (-0.027675787, -0.027238369, 0.0030303528)
                                    float3 physics:diagonalInertia = (0.00003213319, 0.0000671084, 0.00008075841)
                                    float physics:mass = 0.07577727
                                    quatf physics:principalAxes = (0.99759597, -0.010877849, -0.06253952, -0.027798427)

                                    over "rgrip_gear_1" (
                                        prepend apiSchemas = ["PhysicsRigidBodyAPI", "PhysicsMassAPI"]
                                    )
                                    {
                                        point3f physics:centerOfMass = (-2.2601348e-7, -0.0025168115, -1.5579457e-7)
                                        float3 physics:diagonalInertia = (0.000001, 0.000001, 0.000001)
                                        float physics:mass = 0.0025153481
                                        quatf physics:principalAxes = (1, 0, 0, 0)
                                    }

                                    over "rgrip_fin1_1" (
                                        prepend apiSchemas = ["PhysicsRigidBodyAPI", "PhysicsMassAPI"]
                                    )
                                    {
                                        point3f physics:centerOfMass = (-0.0151820695, -0.038685173, 0.019122628)
                                        float3 physics:diagonalInertia = (0.000007, 0.000013, 0.000016)
                                        float physics:mass = 0.033337478
                                        quatf physics:principalAxes = (-0.5, 0.5, 0.5, 0.5)
                                    }

                                    over "rgrip_fin2_1" (
                                        prepend apiSchemas = ["PhysicsRigidBodyAPI", "PhysicsMassAPI"]
                                    )
                                    {
                                        point3f physics:centerOfMass = (0.015181768, -0.038685173, -0.01912294)
                                        float3 physics:diagonalInertia = (0.000007, 0.000013, 0.000016)
                                        float physics:mass = 0.033337478
                                        quatf physics:principalAxes = (-0.5, 0.5, 0.5, 0.5)
                                    }
                                }
                            }
                        }
                    }
                }
            }

            over "lshd_pitch_1" (
                prepend apiSchemas = ["PhysicsRigidBodyAPI", "PhysicsMassAPI"]
            )
            {
                point3f physics:centerOfMass = (-2.2601353e-7, 0.012913512, -1.5564211e-7)
                float3 physics:diagonalInertia = (0.000003, 0.000006, 0.000007)
                float physics:mass = 0.015711742
                quatf physics:principalAxes = (1, 0, 0, 0)

                over "lshd_2xl_1" (
                    prepend apiSchemas = ["PhysicsRigidBodyAPI", "PhysicsMassAPI"]
                )
                {
                    point3f physics:centerOfMass = (0.018213868, 0.004735042, 0.011929064)
                    float3 physics:diagonalInertia = (0.000022, 0.000022807417, 0.000028192582)
                    float physics:mass = 0.0847671
                    quatf physics:principalAxes = (0.7039099, 0.06716326, 0.7039099, 0.06716326)

                    over "lshd_yaw_1" (
                        prepend apiSchemas = ["PhysicsRigidBodyAPI", "PhysicsMassAPI"]
                    )
                    {
                        point3f physics:centerOfMass = (-2.3039313e-7, 0.02029476, -1.297368e-7)
                        float3 physics:diagonalInertia = (0.000004, 0.000005, 0.000007)
                        float physics:mass = 0.016893674
                        quatf physics:principalAxes = (0.70710677, 0, 0.70710677, 0)

                        over "lelbow_1" (
                            prepend apiSchemas = ["PhysicsRigidBodyAPI", "PhysicsMassAPI"]
                        )
                        {
                            point3f physics:centerOfMass = (-2.2597877e-7, 0.028605081, 0.018959703)
                            float3 physics:diagonalInertia = (0.00003190928, 0.00007609072, 0.000098)
                            float physics:mass = 0.0883854
                            quatf physics:principalAxes = (-0.48854005, 0.5112031, 0.48854005, 0.5112031)

                            over "lwrist_1" (
                                prepend apiSchemas = ["PhysicsRigidBodyAPI", "PhysicsMassAPI"]
                            )
                            {
                                point3f physics:centerOfMass = (-0.0007578337, -0.011419244, -0.026135357)
                                float3 physics:diagonalInertia = (0.000023837722, 0.000024, 0.000030162279)
                                float physics:mass = 0.08793325
                                quatf physics:principalAxes = (0.76163715, 0, 0.64800376, 0)

                                over "lgripper_1" (
                                    prepend apiSchemas = ["PhysicsRigidBodyAPI", "PhysicsMassAPI"]
                                )
                                {
                                    point3f physics:centerOfMass = (0.010330924, 0.02723896, 0.0029692932)
                                    float3 physics:diagonalInertia = (0.000032131335, 0.00006697775, 0.00007989092)
                                    float physics:mass = 0.07577727
                                    quatf physics:principalAxes = (0.99640024, 0.050075386, -0.06424876, 0.023475643)

                                    over "lgrip_gear_1" (
                                        prepend apiSchemas = ["PhysicsRigidBodyAPI", "PhysicsMassAPI"]
                                    )
                                    {
                                        point3f physics:centerOfMass = (-2.2601354e-7, 0.0025174015, -1.5543648e-7)
                                        float3 physics:diagonalInertia = (0.000001, 0.000001, 0.000001)
                                        float physics:mass = 0.0025153481
                                        quatf physics:principalAxes = (1, 0, 0, 0)
                                    }

                                    over "lgrip_fin1_1" (
                                        prepend apiSchemas = ["PhysicsRigidBodyAPI", "PhysicsMassAPI"]
                                    )
                                    {
                                        point3f physics:centerOfMass = (-0.015181919, 0.03868576, -0.01912294)
                                        float3 physics:diagonalInertia = (0.000007, 0.000013, 0.000016)
                                        float physics:mass = 0.033337478
                                        quatf physics:principalAxes = (-0.5, 0.5, 0.5, 0.5)
                                    }

                                    over "lgrip_fin2_1" (
                                        prepend apiSchemas = ["PhysicsRigidBodyAPI", "PhysicsMassAPI"]
                                    )
                                    {
                                        point3f physics:centerOfMass = (0.015181617, 0.03868576, 0.019122628)
                                        float3 physics:diagonalInertia = (0.000007, 0.000013, 0.000016)
                                        float physics:mass = 0.033337478
                                        quatf physics:principalAxes = (-0.5, 0.5, 0.5, 0.5)
                                    }
                                }
                            }
                        }
                    }
                }
            }

            over "neck_1" (
                prepend apiSchemas = ["PhysicsRigidBodyAPI", "PhysicsMassAPI"]
            )
            {
                point3f physics:centerOfMass = (-0.000005899304, 0.00050569884, 0.007830289)
                float3 physics:diagonalInertia = (0.000001, 0.000001, 0.000001)
                float physics:mass = 0.0050628283
                quatf physics:principalAxes = (1, 0, 0, 0)

                over "head_1" (
                    prepend apiSchemas = ["PhysicsRigidBodyAPI", "PhysicsMassAPI"]
                )
                {
                    point3f physics:centerOfMass = (0.003344786, 0.014060597, 0.018459715)
                    float3 physics:diagonalInertia = (0.000003, 0.000013, 0.000013)
                    float physics:mass = 0.031003183
                    quatf physics:principalAxes = (0.57363486, 0.57363486, 0.4134526, 0.4134526)
                }
            }

            over "ll1_1" (
                prepend apiSchemas = ["PhysicsRigidBodyAPI", "PhysicsMassAPI"]
            )
            {
                point3f physics:centerOfMass = (-0.00032486816, 2.512322e-7, -0.0153739555)
                float3 physics:diagonalInertia = (0.000002, 0.000007, 0.000008)
                float physics:mass = 0.012917415
                quatf physics:principalAxes = (-0.70710677, 0.70710677, 0, 0)

                over "ll2_1" (
                    prepend apiSchemas = ["PhysicsRigidBodyAPI", "PhysicsMassAPI"]
                )
                {
                    point3f physics:centerOfMass = (-0.040918246, 0.00024752092, -0.012157403)
                    float3 physics:diagonalInertia = (0.000033985918, 0.000094, 0.00010501408)
                    float physics:mass = 0.13078228
                    quatf physics:principalAxes = (-0.70708925, 0.70708925, 0.0049782675, 0.0049782675)

                    over "ll3_1" (
                        prepend apiSchemas = ["PhysicsRigidBodyAPI", "PhysicsMassAPI"]
                    )
                    {
                        point3f physics:centerOfMass = (-0.00006459476, 0.019596398, -0.0643968)
                        float3 physics:diagonalInertia = (0.000016969725, 0.000050030274, 0.000057)
                        float physics:mass = 0.077342235
                        quatf physics:principalAxes = (0.7070258, 0.010700242, 0.7070258, -0.010700242)

                        over "ll4_1" (
                            prepend apiSchemas = ["PhysicsRigidBodyAPI", "PhysicsMassAPI"]
                        )
                        {
                            point3f physics:centerOfMass = (4.2890204e-7, 0.020218099, -0.046242643)
                            float3 physics:diagonalInertia = (0.000009, 0.000017, 0.000024)
                            float physics:mass = 0.022805605
                            quatf physics:principalAxes = (0.70710677, 0, 0.70710677, 0)

                            over "ll5_1" (
                                prepend apiSchemas = ["PhysicsRigidBodyAPI", "PhysicsMassAPI"]
                            )
                            {
                                point3f physics:centerOfMass = (-0.022667661, 0.019245693, 0.012148805)
                                float3 physics:diagonalInertia = (0.000033985918, 0.000094, 0.00010501408)
                                float physics:mass = 0.13078228
                                quatf physics:principalAxes = (-0.70708925, 0.70708925, 0.0049782675, 0.0049782675)

                                over "ll6_1" (
                                    prepend apiSchemas = ["PhysicsRigidBodyAPI", "PhysicsMassAPI"]
                                )
                                {
                                    point3f physics:centerOfMass = (0.02746326, 0.011389976, -0.030840272)
                                    float3 physics:diagonalInertia = (0.00006499359, 0.00016193229, 0.00022107412)
                                    float physics:mass = 0.08571227
                                    quatf physics:principalAxes = (0.9998517, 0.01691997, 0.0032042172, 0.00012032725)
                                }
                            }
                        }
                    }
                }
            }

            over "rl1_1" (
                prepend apiSchemas = ["PhysicsRigidBodyAPI", "PhysicsMassAPI"]
            )
            {
                point3f physics:centerOfMass = (-0.00032486816, 2.512322e-7, -0.0153739555)
                float3 physics:diagonalInertia = (0.000002, 0.000007, 0.000008)
                float physics:mass = 0.012917415
                quatf physics:principalAxes = (-0.70710677, 0.70710677, 0, 0)

                over "rl2_1" (
                    prepend apiSchemas = ["PhysicsRigidBodyAPI", "PhysicsMassAPI"]
                )
                {
                    point3f physics:centerOfMass = (-0.040918246, -0.00024523842, -0.012157403)
                    float3 physics:diagonalInertia = (0.000033985918, 0.000094, 0.00010501408)
                    float physics:mass = 0.13078228
                    quatf physics:principalAxes = (-0.70708925, 0.70708925, -0.0049782675, -0.0049782675)

                    over "rl3_1" (
                        prepend apiSchemas = ["PhysicsRigidBodyAPI", "PhysicsMassAPI"]
                    )
                    {
                        point3f physics:centerOfMass = (-1.7987585e-7, -0.019595943, -0.069596395)
                        float3 physics:diagonalInertia = (0.000016969725, 0.000050030274, 0.000057)
                        float physics:mass = 0.077342235
                        quatf physics:principalAxes = (0.7070258, -0.010700242, 0.7070258, 0.010700242)

                        over "rl4_1" (
                            prepend apiSchemas = ["PhysicsRigidBodyAPI", "PhysicsMassAPI"]
                        )
                        {
                            point3f physics:centerOfMass = (-1.562105e-7, -0.020217644, -0.046243228)
                            float3 physics:diagonalInertia = (0.000009, 0.000017, 0.000024)
                            float physics:mass = 0.022805605
                            quatf physics:principalAxes = (0.70710677, 0, 0.70710677, 0)

                            over "rl5_1" (
                                prepend apiSchemas = ["PhysicsRigidBodyAPI", "PhysicsMassAPI"]
                            )
                            {
                                point3f physics:centerOfMass = (-0.022668246, -0.019247066, 0.012149204)
                                float3 physics:diagonalInertia = (0.000033985918, 0.000094, 0.00010501408)
                                float physics:mass = 0.13078228
                                quatf physics:principalAxes = (-0.70708925, 0.70708925, -0.0049782675, -0.0049782675)

                                over "rl6_1" (
                                    prepend apiSchemas = ["PhysicsRigidBodyAPI", "PhysicsMassAPI"]
                                )
                                {
                                    point3f physics:centerOfMass = (0.027462674, -0.011389522, -0.030839873)
                                    float3 physics:diagonalInertia = (0.00006499359, 0.00016193229, 0.00022107412)
                                    float physics:mass = 0.08571227
                                    quatf physics:principalAxes = (0.9998517, -0.01691997, 0.0032042172, -0.00012032725)
                                }
                            }
                        }
                    }
                }
            }
        }
    }

    over "Physics"
    {
        def PhysicsRevoluteJoint "lgripper_joint" (
            prepend apiSchemas = ["PhysicsDriveAPI:angular", "PhysicsJointStateAPI:angular"]
        )
        {
            float drive:angular:physics:damping = 10
            float drive:angular:physics:maxForce = 100
            uniform token physics:axis = "Y"
            custom rel physics:body0
            prepend rel physics:body0 = </humanoid_urdf/Geometry/base_link/lshd_pitch_1/lshd_2xl_1/lshd_yaw_1/lelbow_1/lwrist_1/lgripper_1>
            custom rel physics:body1
            prepend rel physics:body1 = </humanoid_urdf/Geometry/base_link/lshd_pitch_1/lshd_2xl_1/lshd_yaw_1/lelbow_1/lwrist_1/lgripper_1/lgrip_gear_1>
            point3f physics:localPos0 = (0.019, 0.0397, 0)
            point3f physics:localPos1 = (0, 0, 0)
            quatf physics:localRot0 = (1, 0, 0, 0)
            quatf physics:localRot1 = (1, 0, 0, 0)
            float physics:lowerLimit = -300.0007
            float physics:upperLimit = 50.002026
            custom float urdf:dynamics:damping = 10
            custom float urdf:dynamics:friction = 0
            custom float urdf:limit:effort = 100
            custom float urdf:limit:velocity = 100
        }

        def PhysicsPrismaticJoint "lgrip_fin1_slider" (
            prepend apiSchemas = ["NewtonMimicAPI", "PhysicsDriveAPI:linear", "PhysicsJointStateAPI:linear"]
        )
        {
            float drive:linear:physics:damping = 10
            float drive:linear:physics:maxForce = 100
            float newton:mimicCoef1 = 0.00869
            rel newton:mimicJoint = </humanoid_urdf/Physics/lgripper_joint>
            uniform token physics:axis = "X"
            custom rel physics:body0
            prepend rel physics:body0 = </humanoid_urdf/Geometry/base_link/lshd_pitch_1/lshd_2xl_1/lshd_yaw_1/lelbow_1/lwrist_1/lgripper_1>
            custom rel physics:body1
            prepend rel physics:body1 = </humanoid_urdf/Geometry/base_link/lshd_pitch_1/lshd_2xl_1/lshd_yaw_1/lelbow_1/lwrist_1/lgripper_1/lgrip_fin1_1>
            point3f physics:localPos0 = (0.018907, 0.0389, 0.0192)
            point3f physics:localPos1 = (0, 0, 0)
            quatf physics:localRot0 = (1, 0, 0, 0)
            quatf physics:localRot1 = (1, 0, 0, 0)
            float physics:lowerLimit = -0.02
            float physics:upperLimit = 0.007
            custom float urdf:dynamics:damping = 10
            custom float urdf:dynamics:friction = 0
            custom float urdf:limit:effort = 100
            custom float urdf:limit:velocity = 100
        }

        def PhysicsPrismaticJoint "lgrip_fin2_slider" (
            prepend apiSchemas = ["NewtonMimicAPI", "PhysicsDriveAPI:linear", "PhysicsJointStateAPI:linear"]
        )
        {
            float drive:linear:physics:damping = 10
            float drive:linear:physics:maxForce = 100
            float newton:mimicCoef1 = -1
            rel newton:mimicJoint = </humanoid_urdf/Physics/lgrip_fin1_slider>
            uniform token physics:axis = "X"
            custom rel physics:body0
            prepend rel physics:body0 = </humanoid_urdf/Geometry/base_link/lshd_pitch_1/lshd_2xl_1/lshd_yaw_1/lelbow_1/lwrist_1/lgripper_1>
            custom rel physics:body1
            prepend rel physics:body1 = </humanoid_urdf/Geometry/base_link/lshd_pitch_1/lshd_2xl_1/lshd_yaw_1/lelbow_1/lwrist_1/lgripper_1/lgrip_fin2_1>
            point3f physics:localPos0 = (0.019, 0.0389, -0.0192)
            point3f physics:localPos1 = (0, 0, 0)
            quatf physics:localRot0 = (1, 0, 0, 0)
            quatf physics:localRot1 = (1, 0, 0, 0)
            float physics:lowerLimit = -0.007
            float physics:upperLimit = 0.02
            custom float urdf:dynamics:damping = 10
            custom float urdf:dynamics:friction = 0
            custom float urdf:limit:effort = 100
            custom float urdf:limit:velocity = 100
        }

        def PhysicsRevoluteJoint "lshd_yaw_joint" (
            prepend apiSchemas = ["PhysicsDriveAPI:angular", "PhysicsJointStateAPI:angular"]
        )
        {
            float drive:angular:physics:damping = 10
            float drive:angular:physics:maxForce = 100
            uniform token physics:axis = "X"
            custom rel physics:body0
            prepend rel physics:body0 = </humanoid_urdf/Geometry/base_link/lshd_pitch_1>
            custom rel physics:body1
            prepend rel physics:body1 = </humanoid_urdf/Geometry/base_link/lshd_pitch_1/lshd_2xl_1>
            point3f physics:localPos0 = (-0.019, 0.027, 0)
            point3f physics:localPos1 = (0, 0, 0)
            quatf physics:localRot0 = (1, 0, 0, 0)
            quatf physics:localRot1 = (1, 0, 0, 0)
            float physics:lowerLimit = -89.999985
            float physics:upperLimit = 20.000008
            custom float urdf:dynamics:damping = 10
            custom float urdf:dynamics:friction = 0
            custom float urdf:limit:effort = 100
            custom float urdf:limit:velocity = 100
        }

        def PhysicsRevoluteJoint "lwrist_pitch_joint" (
            prepend apiSchemas = ["PhysicsDriveAPI:angular", "PhysicsJointStateAPI:angular"]
        )
        {
            float drive:angular:physics:damping = 10
            float drive:angular:physics:maxForce = 100
            uniform token physics:axis = "Z"
            custom rel physics:body0
            prepend rel physics:body0 = </humanoid_urdf/Geometry/base_link/lshd_pitch_1/lshd_2xl_1/lshd_yaw_1/lelbow_1>
            custom rel physics:body1
            prepend rel physics:body1 = </humanoid_urdf/Geometry/base_link/lshd_pitch_1/lshd_2xl_1/lshd_yaw_1/lelbow_1/lwrist_1>
            point3f physics:localPos0 = (0, 0.1002, 0.045)
            point3f physics:localPos1 = (0, 0, 0)
            quatf physics:localRot0 = (-0, -1, 0, 0)
            quatf physics:localRot1 = (-0, -1, 0, 0)
            float physics:lowerLimit = -89.999985
            float physics:upperLimit = 89.999985
            custom float urdf:dynamics:damping = 10
            custom float urdf:dynamics:friction = 0
            custom float urdf:limit:effort = 100
            custom float urdf:limit:velocity = 100
        }

        def PhysicsRevoluteJoint "lwrist_yaw_joint" (
            prepend apiSchemas = ["PhysicsDriveAPI:angular", "PhysicsJointStateAPI:angular"]
        )
        {
            float drive:angular:physics:damping = 10
            float drive:angular:physics:maxForce = 100
            uniform token physics:axis = "X"
            custom rel physics:body0
            prepend rel physics:body0 = </humanoid_urdf/Geometry/base_link/lshd_pitch_1/lshd_2xl_1/lshd_yaw_1/lelbow_1/lwrist_1>
            custom rel physics:body1
            prepend rel physics:body1 = </humanoid_urdf/Geometry/base_link/lshd_pitch_1/lshd_2xl_1/lshd_yaw_1/lelbow_1/lwrist_1/lgripper_1>
            point3f physics:localPos0 = (-0.019, 0, -0.0287)
            point3f physics:localPos1 = (0, 0, 0)
            quatf physics:localRot0 = (-0, 0, -1, 0)
            quatf physics:localRot1 = (-0, 0, -1, 0)
            float physics:lowerLimit = -20.000008
            float physics:upperLimit = 20.000008
            custom float urdf:dynamics:damping = 10
            custom float urdf:dynamics:friction = 0
            custom float urdf:limit:effort = 100
            custom float urdf:limit:velocity = 100
        }

        def PhysicsRevoluteJoint "rwrist_pitch_joint" (
            prepend apiSchemas = ["PhysicsDriveAPI:angular", "PhysicsJointStateAPI:angular"]
        )
        {
            float drive:angular:physics:damping = 10
            float drive:angular:physics:maxForce = 100
            uniform token physics:axis = "Z"
            custom rel physics:body0
            prepend rel physics:body0 = </humanoid_urdf/Geometry/base_link/rshd_pitch_1/rshd_2xl_1/rshd_yaw_1/relbow_1>
            custom rel physics:body1
            prepend rel physics:body1 = </humanoid_urdf/Geometry/base_link/rshd_pitch_1/rshd_2xl_1/rshd_yaw_1/relbow_1/rwrist_1>
            point3f physics:localPos0 = (0, -0.1002, 0.045)
            point3f physics:localPos1 = (0, 0, 0)
            quatf physics:localRot0 = (-0, -1, 0, 0)
            quatf physics:localRot1 = (-0, -1, 0, 0)
            float physics:lowerLimit = -89.999985
            float physics:upperLimit = 89.999985
            custom float urdf:dynamics:damping = 10
            custom float urdf:dynamics:friction = 0
            custom float urdf:limit:effort = 100
            custom float urdf:limit:velocity = 100
        }

        def PhysicsRevoluteJoint "rwrist_yaw_joint" (
            prepend apiSchemas = ["PhysicsDriveAPI:angular", "PhysicsJointStateAPI:angular"]
        )
        {
            float drive:angular:physics:damping = 10
            float drive:angular:physics:maxForce = 100
            uniform token physics:axis = "X"
            custom rel physics:body0
            prepend rel physics:body0 = </humanoid_urdf/Geometry/base_link/rshd_pitch_1/rshd_2xl_1/rshd_yaw_1/relbow_1/rwrist_1>
            custom rel physics:body1
            prepend rel physics:body1 = </humanoid_urdf/Geometry/base_link/rshd_pitch_1/rshd_2xl_1/rshd_yaw_1/relbow_1/rwrist_1/rgripper_1>
            point3f physics:localPos0 = (0.019, 0, -0.0287)
            point3f physics:localPos1 = (0, 0, 0)
            quatf physics:localRot0 = (1, 0, 0, 0)
            quatf physics:localRot1 = (1, 0, 0, 0)
            float physics:lowerLimit = -20.000008
            float physics:upperLimit = 20.000008
            custom float urdf:dynamics:damping = 10
            custom float urdf:dynamics:friction = 0
            custom float urdf:limit:effort = 100
            custom float urdf:limit:velocity = 100
        }

        def PhysicsRevoluteJoint "rgripper_joint" (
            prepend apiSchemas = ["PhysicsDriveAPI:angular", "PhysicsJointStateAPI:angular"]
        )
        {
            float drive:angular:physics:damping = 10
            float drive:angular:physics:maxForce = 100
            uniform token physics:axis = "Y"
            custom rel physics:body0
            prepend rel physics:body0 = </humanoid_urdf/Geometry/base_link/rshd_pitch_1/rshd_2xl_1/rshd_yaw_1/relbow_1/rwrist_1/rgripper_1>
            custom rel physics:body1
            prepend rel physics:body1 = </humanoid_urdf/Geometry/base_link/rshd_pitch_1/rshd_2xl_1/rshd_yaw_1/relbow_1/rwrist_1/rgripper_1/rgrip_gear_1>
            point3f physics:localPos0 = (-0.019, -0.0397, 0)
            point3f physics:localPos1 = (0, 0, 0)
            quatf physics:localRot0 = (1, 0, 0, 0)
            quatf physics:localRot1 = (1, 0, 0, 0)
            float physics:lowerLimit = -300.0007
            float physics:upperLimit = 50.002026
            custom float urdf:dynamics:damping = 10
            custom float urdf:dynamics:friction = 0
            custom float urdf:limit:effort = 100
            custom float urdf:limit:velocity = 100
        }

        def PhysicsPrismaticJoint "rgrip_fin1_slider" (
            prepend apiSchemas = ["NewtonMimicAPI", "PhysicsDriveAPI:linear", "PhysicsJointStateAPI:linear"]
        )
        {
            float drive:linear:physics:damping = 10
            float drive:linear:physics:maxForce = 100
            float newton:mimicCoef1 = 0.00869
            rel newton:mimicJoint = </humanoid_urdf/Physics/rgripper_joint>
            uniform token physics:axis = "X"
            custom rel physics:body0
            prepend rel physics:body0 = </humanoid_urdf/Geometry/base_link/rshd_pitch_1/rshd_2xl_1/rshd_yaw_1/relbow_1/rwrist_1/rgripper_1>
            custom rel physics:body1
            prepend rel physics:body1 = </humanoid_urdf/Geometry/base_link/rshd_pitch_1/rshd_2xl_1/rshd_yaw_1/relbow_1/rwrist_1/rgripper_1/rgrip_fin1_1>
            point3f physics:localPos0 = (-0.019, -0.0389, -0.0192)
            point3f physics:localPos1 = (0, 0, 0)
            quatf physics:localRot0 = (1, 0, 0, 0)
            quatf physics:localRot1 = (1, 0, 0, 0)
            float physics:lowerLimit = -0.02
            float physics:upperLimit = 0.007
            custom float urdf:dynamics:damping = 10
            custom float urdf:dynamics:friction = 0
            custom float urdf:limit:effort = 100
            custom float urdf:limit:velocity = 100
        }

        def PhysicsPrismaticJoint "rgrip_fin2_slider" (
            prepend apiSchemas = ["NewtonMimicAPI", "PhysicsDriveAPI:linear", "PhysicsJointStateAPI:linear"]
        )
        {
            float drive:linear:physics:damping = 10
            float drive:linear:physics:maxForce = 100
            float newton:mimicCoef1 = -1
            rel newton:mimicJoint = </humanoid_urdf/Physics/rgrip_fin1_slider>
            uniform token physics:axis = "X"
            custom rel physics:body0
            prepend rel physics:body0 = </humanoid_urdf/Geometry/base_link/rshd_pitch_1/rshd_2xl_1/rshd_yaw_1/relbow_1/rwrist_1/rgripper_1>
            custom rel physics:body1
            prepend rel physics:body1 = </humanoid_urdf/Geometry/base_link/rshd_pitch_1/rshd_2xl_1/rshd_yaw_1/relbow_1/rwrist_1/rgripper_1/rgrip_fin2_1>
            point3f physics:localPos0 = (-0.019093, -0.0389, 0.0192)
            point3f physics:localPos1 = (0, 0, 0)
            quatf physics:localRot0 = (1, 0, 0, 0)
            quatf physics:localRot1 = (1, 0, 0, 0)
            float physics:lowerLimit = -0.007
            float physics:upperLimit = 0.02
            custom float urdf:dynamics:damping = 10
            custom float urdf:dynamics:friction = 0
            custom float urdf:limit:effort = 100
            custom float urdf:limit:velocity = 100
        }

        def PhysicsRevoluteJoint "rshd_pitch_joint" (
            prepend apiSchemas = ["PhysicsDriveAPI:angular", "PhysicsJointStateAPI:angular"]
        )
        {
            float drive:angular:physics:damping = 10
            float drive:angular:physics:maxForce = 100
            uniform token physics:axis = "Y"
            custom rel physics:body0
            prepend rel physics:body0 = </humanoid_urdf/Geometry/base_link>
            custom rel physics:body1
            prepend rel physics:body1 = </humanoid_urdf/Geometry/base_link/rshd_pitch_1>
            point3f physics:localPos0 = (0.018924, -0.084004, 0.381916)
            point3f physics:localPos1 = (0, 0, 0)
            quatf physics:localRot0 = (-0, -1, 0, 0)
            quatf physics:localRot1 = (-0, -1, 0, 0)
            float physics:lowerLimit = -179.99997
            float physics:upperLimit = 179.99997
            custom float urdf:dynamics:damping = 10
            custom float urdf:dynamics:friction = 0
            custom float urdf:limit:effort = 100
            custom float urdf:limit:velocity = 100
        }

        def PhysicsRevoluteJoint "lshd_pitch_joint" (
            prepend apiSchemas = ["PhysicsDriveAPI:angular", "PhysicsJointStateAPI:angular"]
        )
        {
            float drive:angular:physics:damping = 10
            float drive:angular:physics:maxForce = 100
            uniform token physics:axis = "Y"
            custom rel physics:body0
            prepend rel physics:body0 = </humanoid_urdf/Geometry/base_link>
            custom rel physics:body1
            prepend rel physics:body1 = </humanoid_urdf/Geometry/base_link/lshd_pitch_1>
            point3f physics:localPos0 = (0.018924, 0.080206, 0.381916)
            point3f physics:localPos1 = (0, 0, 0)
            quatf physics:localRot0 = (1, 0, 0, 0)
            quatf physics:localRot1 = (1, 0, 0, 0)
            float physics:lowerLimit = -179.99997
            float physics:upperLimit = 179.99997
            custom float urdf:dynamics:damping = 10
            custom float urdf:dynamics:friction = 0
            custom float urdf:limit:effort = 100
            custom float urdf:limit:velocity = 100
        }

        def PhysicsRevoluteJoint "neck_roll_joint" (
            prepend apiSchemas = ["PhysicsDriveAPI:angular", "PhysicsJointStateAPI:angular"]
        )
        {
            float drive:angular:physics:damping = 10
            float drive:angular:physics:maxForce = 100
            uniform token physics:axis = "Z"
            custom rel physics:body0
            prepend rel physics:body0 = </humanoid_urdf/Geometry/base_link>
            custom rel physics:body1
            prepend rel physics:body1 = </humanoid_urdf/Geometry/base_link/neck_1>
            point3f physics:localPos0 = (0.009136, -0.002011, 0.419533)
            point3f physics:localPos1 = (0, 0, 0)
            quatf physics:localRot0 = (-0, -1, 0, 0)
            quatf physics:localRot1 = (-0, -1, 0, 0)
            float physics:lowerLimit = -89.999985
            float physics:upperLimit = 89.999985
            custom float urdf:dynamics:damping = 10
            custom float urdf:dynamics:friction = 0
            custom float urdf:limit:effort = 100
            custom float urdf:limit:velocity = 100
        }

        def PhysicsRevoluteJoint "neck_pitch_joint" (
            prepend apiSchemas = ["PhysicsDriveAPI:angular", "PhysicsJointStateAPI:angular"]
        )
        {
            float drive:angular:physics:damping = 10
            float drive:angular:physics:maxForce = 100
            uniform token physics:axis = "Y"
            custom rel physics:body0
            prepend rel physics:body0 = </humanoid_urdf/Geometry/base_link/neck_1>
            custom rel physics:body1
            prepend rel physics:body1 = </humanoid_urdf/Geometry/base_link/neck_1/head_1>
            point3f physics:localPos0 = (-0.000091, -0.014046, 0.018566)
            point3f physics:localPos1 = (0, 0, 0)
            quatf physics:localRot0 = (-0, -1, 0, 0)
            quatf physics:localRot1 = (-0, -1, 0, 0)
            float physics:lowerLimit = -89.999985
            float physics:upperLimit = 89.999985
            custom float urdf:dynamics:damping = 10
            custom float urdf:dynamics:friction = 0
            custom float urdf:limit:effort = 100
            custom float urdf:limit:velocity = 100
        }

        def PhysicsRevoluteJoint "lbase_joint" (
            prepend apiSchemas = ["PhysicsDriveAPI:angular", "PhysicsJointStateAPI:angular"]
        )
        {
            float drive:angular:physics:damping = 10
            float drive:angular:physics:maxForce = 100
            uniform token physics:axis = "Z"
            custom rel physics:body0
            prepend rel physics:body0 = </humanoid_urdf/Geometry/base_link>
            custom rel physics:body1
            prepend rel physics:body1 = </humanoid_urdf/Geometry/base_link/ll1_1>
            point3f physics:localPos0 = (0.001007, 0.05803, 0.258033)
            point3f physics:localPos1 = (0, 0, 0)
            quatf physics:localRot0 = (-0, -1, 0, 0)
            quatf physics:localRot1 = (-0, -1, 0, 0)
            float physics:lowerLimit = -89.999985
            float physics:upperLimit = 0
            custom float urdf:dynamics:damping = 10
            custom float urdf:dynamics:friction = 0
            custom float urdf:limit:effort = 100
            custom float urdf:limit:velocity = 100
        }

        def PhysicsRevoluteJoint "ll1_joint" (
            prepend apiSchemas = ["PhysicsDriveAPI:angular", "PhysicsJointStateAPI:angular"]
        )
        {
            float drive:angular:physics:damping = 10
            float drive:angular:physics:maxForce = 100
            uniform token physics:axis = "X"
            custom rel physics:body0
            prepend rel physics:body0 = </humanoid_urdf/Geometry/base_link/ll1_1>
            custom rel physics:body1
            prepend rel physics:body1 = </humanoid_urdf/Geometry/base_link/ll1_1/ll2_1>
            point3f physics:localPos0 = (0.02042, 0, -0.0345)
            point3f physics:localPos1 = (0, 0, 0)
            quatf physics:localRot0 = (-0, 0, -1, 0)
            quatf physics:localRot1 = (-0, 0, -1, 0)
            float physics:lowerLimit = -89.999985
            float physics:upperLimit = 20.000008
            custom float urdf:dynamics:damping = 10
            custom float urdf:dynamics:friction = 0
            custom float urdf:limit:effort = 100
            custom float urdf:limit:velocity = 100
        }

        def PhysicsRevoluteJoint "rbase_joint" (
            prepend apiSchemas = ["PhysicsDriveAPI:angular", "PhysicsJointStateAPI:angular"]
        )
        {
            float drive:angular:physics:damping = 10
            float drive:angular:physics:maxForce = 100
            uniform token physics:axis = "Z"
            custom rel physics:body0
            prepend rel physics:body0 = </humanoid_urdf/Geometry/base_link>
            custom rel physics:body1
            prepend rel physics:body1 = </humanoid_urdf/Geometry/base_link/rl1_1>
            point3f physics:localPos0 = (0.001007, -0.06197, 0.258033)
            point3f physics:localPos1 = (0, 0, 0)
            quatf physics:localRot0 = (-0, -1, 0, 0)
            quatf physics:localRot1 = (-0, -1, 0, 0)
            float physics:lowerLimit = 0
            float physics:upperLimit = 89.999985
            custom float urdf:dynamics:damping = 10
            custom float urdf:dynamics:friction = 0
            custom float urdf:limit:effort = 100
            custom float urdf:limit:velocity = 100
        }

        def PhysicsRevoluteJoint "rl3_joint" (
            prepend apiSchemas = ["PhysicsDriveAPI:angular", "PhysicsJointStateAPI:angular"]
        )
        {
            float drive:angular:physics:damping = 10
            float drive:angular:physics:maxForce = 100
            uniform token physics:axis = "Y"
            custom rel physics:body0
            prepend rel physics:body0 = </humanoid_urdf/Geometry/base_link/rl1_1/rl2_1/rl3_1>
            custom rel physics:body1
            prepend rel physics:body1 = </humanoid_urdf/Geometry/base_link/rl1_1/rl2_1/rl3_1/rl4_1>
            point3f physics:localPos0 = (0, 0, -0.092493)
            point3f physics:localPos1 = (0, 0, 0)
            quatf physics:localRot0 = (1, 0, 0, 0)
            quatf physics:localRot1 = (1, 0, 0, 0)
            float physics:lowerLimit = 0
            float physics:upperLimit = 89.999985
            custom float urdf:dynamics:damping = 10
            custom float urdf:dynamics:friction = 0
            custom float urdf:limit:effort = 100
            custom float urdf:limit:velocity = 100
        }

        def PhysicsRevoluteJoint "rl5_joint" (
            prepend apiSchemas = ["PhysicsDriveAPI:angular", "PhysicsJointStateAPI:angular"]
        )
        {
            float drive:angular:physics:damping = 10
            float drive:angular:physics:maxForce = 100
            uniform token physics:axis = "X"
            custom rel physics:body0
            prepend rel physics:body0 = </humanoid_urdf/Geometry/base_link/rl1_1/rl2_1/rl3_1/rl4_1/rl5_1>
            custom rel physics:body1
            prepend rel physics:body1 = </humanoid_urdf/Geometry/base_link/rl1_1/rl2_1/rl3_1/rl4_1/rl5_1/rl6_1>
            point3f physics:localPos0 = (-0.029239, -0.019, 0)
            point3f physics:localPos1 = (0, 0, 0)
            quatf physics:localRot0 = (1, 0, 0, 0)
            quatf physics:localRot1 = (1, 0, 0, 0)
            float physics:lowerLimit = -89.999985
            float physics:upperLimit = 20.000008
            custom float urdf:dynamics:damping = 10
            custom float urdf:dynamics:friction = 0
            custom float urdf:limit:effort = 100
            custom float urdf:limit:velocity = 100
        }

        def PhysicsRevoluteJoint "ll2_joint" (
            prepend apiSchemas = ["PhysicsDriveAPI:angular", "PhysicsJointStateAPI:angular"]
        )
        {
            float drive:angular:physics:damping = 10
            float drive:angular:physics:maxForce = 100
            uniform token physics:axis = "Y"
            custom rel physics:body0
            prepend rel physics:body0 = </humanoid_urdf/Geometry/base_link/ll1_1/ll2_1>
            custom rel physics:body1
            prepend rel physics:body1 = </humanoid_urdf/Geometry/base_link/ll1_1/ll2_1/ll3_1>
            point3f physics:localPos0 = (-0.01825, -0.019, -0.000008)
            point3f physics:localPos1 = (0, 0, 0)
            quatf physics:localRot0 = (-0, -1, 0, 0)
            quatf physics:localRot1 = (-0, -1, 0, 0)
            float physics:lowerLimit = -20.000008
            float physics:upperLimit = 89.999985
            custom float urdf:dynamics:damping = 10
            custom float urdf:dynamics:friction = 0
            custom float urdf:limit:effort = 100
            custom float urdf:limit:velocity = 100
        }

        def PhysicsRevoluteJoint "ll3_joint" (
            prepend apiSchemas = ["PhysicsDriveAPI:angular", "PhysicsJointStateAPI:angular"]
        )
        {
            float drive:angular:physics:damping = 10
            float drive:angular:physics:maxForce = 100
            uniform token physics:axis = "Y"
            custom rel physics:body0
            prepend rel physics:body0 = </humanoid_urdf/Geometry/base_link/ll1_1/ll2_1/ll3_1>
            custom rel physics:body1
            prepend rel physics:body1 = </humanoid_urdf/Geometry/base_link/ll1_1/ll2_1/ll3_1/ll4_1>
            point3f physics:localPos0 = (-0.000065, 0, -0.087294)
            point3f physics:localPos1 = (0, 0, 0)
            quatf physics:localRot0 = (-0, -1, 0, 0)
            quatf physics:localRot1 = (-0, -1, 0, 0)
            float physics:lowerLimit = -89.999985
            float physics:upperLimit = 0
            custom float urdf:dynamics:damping = 10
            custom float urdf:dynamics:friction = 0
            custom float urdf:limit:effort = 100
            custom float urdf:limit:velocity = 100
        }

        def PhysicsRevoluteJoint "ll5_joint" (
            prepend apiSchemas = ["PhysicsDriveAPI:angular", "PhysicsJointStateAPI:angular"]
        )
        {
            float drive:angular:physics:damping = 10
            float drive:angular:physics:maxForce = 100
            uniform token physics:axis = "X"
            custom rel physics:body0
            prepend rel physics:body0 = </humanoid_urdf/Geometry/base_link/ll1_1/ll2_1/ll3_1/ll4_1/ll5_1>
            custom rel physics:body1
            prepend rel physics:body1 = </humanoid_urdf/Geometry/base_link/ll1_1/ll2_1/ll3_1/ll4_1/ll5_1/ll6_1>
            point3f physics:localPos0 = (-0.029239, 0.019, 0)
            point3f physics:localPos1 = (0, 0, 0)
            quatf physics:localRot0 = (1, 0, 0, 0)
            quatf physics:localRot1 = (1, 0, 0, 0)
            float physics:lowerLimit = -20.000008
            float physics:upperLimit = 89.999985
            custom float urdf:dynamics:damping = 10
            custom float urdf:dynamics:friction = 0
            custom float urdf:limit:effort = 100
            custom float urdf:limit:velocity = 100
        }

        def PhysicsRevoluteJoint "rl1_joint" (
            prepend apiSchemas = ["PhysicsDriveAPI:angular", "PhysicsJointStateAPI:angular"]
        )
        {
            float drive:angular:physics:damping = 10
            float drive:angular:physics:maxForce = 100
            uniform token physics:axis = "X"
            custom rel physics:body0
            prepend rel physics:body0 = </humanoid_urdf/Geometry/base_link/rl1_1>
            custom rel physics:body1
            prepend rel physics:body1 = </humanoid_urdf/Geometry/base_link/rl1_1/rl2_1>
            point3f physics:localPos0 = (0.02042, 0, -0.0345)
            point3f physics:localPos1 = (0, 0, 0)
            quatf physics:localRot0 = (-0, 0, -1, 0)
            quatf physics:localRot1 = (-0, 0, -1, 0)
            float physics:lowerLimit = -20.000008
            float physics:upperLimit = 89.999985
            custom float urdf:dynamics:damping = 10
            custom float urdf:dynamics:friction = 0
            custom float urdf:limit:effort = 100
            custom float urdf:limit:velocity = 100
        }

        def PhysicsRevoluteJoint "rl2_joint" (
            prepend apiSchemas = ["PhysicsDriveAPI:angular", "PhysicsJointStateAPI:angular"]
        )
        {
            float drive:angular:physics:damping = 10
            float drive:angular:physics:maxForce = 100
            uniform token physics:axis = "Y"
            custom rel physics:body0
            prepend rel physics:body0 = </humanoid_urdf/Geometry/base_link/rl1_1/rl2_1>
            custom rel physics:body1
            prepend rel physics:body1 = </humanoid_urdf/Geometry/base_link/rl1_1/rl2_1/rl3_1>
            point3f physics:localPos0 = (-0.01825, 0.019, -0.000008)
            point3f physics:localPos1 = (0, 0, 0)
            quatf physics:localRot0 = (1, 0, 0, 0)
            quatf physics:localRot1 = (1, 0, 0, 0)
            float physics:lowerLimit = -89.999985
            float physics:upperLimit = 20.000008
            custom float urdf:dynamics:damping = 10
            custom float urdf:dynamics:friction = 0
            custom float urdf:limit:effort = 100
            custom float urdf:limit:velocity = 100
        }

        def PhysicsRevoluteJoint "lshd_roll_joint" (
            prepend apiSchemas = ["PhysicsDriveAPI:angular", "PhysicsJointStateAPI:angular"]
        )
        {
            float drive:angular:physics:damping = 10
            float drive:angular:physics:maxForce = 100
            uniform token physics:axis = "Y"
            custom rel physics:body0
            prepend rel physics:body0 = </humanoid_urdf/Geometry/base_link/lshd_pitch_1/lshd_2xl_1>
            custom rel physics:body1
            prepend rel physics:body1 = </humanoid_urdf/Geometry/base_link/lshd_pitch_1/lshd_2xl_1/lshd_yaw_1>
            point3f physics:localPos0 = (0.019, 0.026, 0)
            point3f physics:localPos1 = (0, 0, 0)
            quatf physics:localRot0 = (1, 0, 0, 0)
            quatf physics:localRot1 = (1, 0, 0, 0)
            float physics:lowerLimit = -89.999985
            float physics:upperLimit = 89.999985
            custom float urdf:dynamics:damping = 10
            custom float urdf:dynamics:friction = 0
            custom float urdf:limit:effort = 100
            custom float urdf:limit:velocity = 100
        }

        def PhysicsRevoluteJoint "lelbow_joint" (
            prepend apiSchemas = ["PhysicsDriveAPI:angular", "PhysicsJointStateAPI:angular"]
        )
        {
            float drive:angular:physics:damping = 10
            float drive:angular:physics:maxForce = 100
            uniform token physics:axis = "Z"
            custom rel physics:body0
            prepend rel physics:body0 = </humanoid_urdf/Geometry/base_link/lshd_pitch_1/lshd_2xl_1/lshd_yaw_1>
            custom rel physics:body1
            prepend rel physics:body1 = </humanoid_urdf/Geometry/base_link/lshd_pitch_1/lshd_2xl_1/lshd_yaw_1/lelbow_1>
            point3f physics:localPos0 = (0, 0.0437, -0.019)
            point3f physics:localPos1 = (0, 0, 0)
            quatf physics:localRot0 = (-0, -1, 0, 0)
            quatf physics:localRot1 = (-0, -1, 0, 0)
            float physics:lowerLimit = -119.99999
            float physics:upperLimit = 119.99999
            custom float urdf:dynamics:damping = 10
            custom float urdf:dynamics:friction = 0
            custom float urdf:limit:effort = 100
            custom float urdf:limit:velocity = 100
        }

        def PhysicsRevoluteJoint "rshd_roll_joint" (
            prepend apiSchemas = ["PhysicsDriveAPI:angular", "PhysicsJointStateAPI:angular"]
        )
        {
            float drive:angular:physics:damping = 10
            float drive:angular:physics:maxForce = 100
            uniform token physics:axis = "Y"
            custom rel physics:body0
            prepend rel physics:body0 = </humanoid_urdf/Geometry/base_link/rshd_pitch_1/rshd_2xl_1>
            custom rel physics:body1
            prepend rel physics:body1 = </humanoid_urdf/Geometry/base_link/rshd_pitch_1/rshd_2xl_1/rshd_yaw_1>
            point3f physics:localPos0 = (0.018, -0.026, 0)
            point3f physics:localPos1 = (0, 0, 0)
            quatf physics:localRot0 = (-0, -1, 0, 0)
            quatf physics:localRot1 = (-0, -1, 0, 0)
            float physics:lowerLimit = -89.999985
            float physics:upperLimit = 89.999985
            custom float urdf:dynamics:damping = 10
            custom float urdf:dynamics:friction = 0
            custom float urdf:limit:effort = 100
            custom float urdf:limit:velocity = 100
        }

        def PhysicsRevoluteJoint "relbow_joint" (
            prepend apiSchemas = ["PhysicsDriveAPI:angular", "PhysicsJointStateAPI:angular"]
        )
        {
            float drive:angular:physics:damping = 10
            float drive:angular:physics:maxForce = 100
            uniform token physics:axis = "Z"
            custom rel physics:body0
            prepend rel physics:body0 = </humanoid_urdf/Geometry/base_link/rshd_pitch_1/rshd_2xl_1/rshd_yaw_1>
            custom rel physics:body1
            prepend rel physics:body1 = </humanoid_urdf/Geometry/base_link/rshd_pitch_1/rshd_2xl_1/rshd_yaw_1/relbow_1>
            point3f physics:localPos0 = (0, -0.0437, -0.019)
            point3f physics:localPos1 = (0, 0, 0)
            quatf physics:localRot0 = (-0, -1, 0, 0)
            quatf physics:localRot1 = (-0, -1, 0, 0)
            float physics:lowerLimit = -119.99999
            float physics:upperLimit = 119.99999
            custom float urdf:dynamics:damping = 10
            custom float urdf:dynamics:friction = 0
            custom float urdf:limit:effort = 100
            custom float urdf:limit:velocity = 100
        }

        def PhysicsRevoluteJoint "ll4_joint" (
            prepend apiSchemas = ["PhysicsDriveAPI:angular", "PhysicsJointStateAPI:angular"]
        )
        {
            float drive:angular:physics:damping = 10
            float drive:angular:physics:maxForce = 100
            uniform token physics:axis = "Y"
            custom rel physics:body0
            prepend rel physics:body0 = </humanoid_urdf/Geometry/base_link/ll1_1/ll2_1/ll3_1/ll4_1>
            custom rel physics:body1
            prepend rel physics:body1 = </humanoid_urdf/Geometry/base_link/ll1_1/ll2_1/ll3_1/ll4_1/ll5_1>
            point3f physics:localPos0 = (0, 0, -0.092485)
            point3f physics:localPos1 = (0, 0, 0)
            quatf physics:localRot0 = (1, 0, 0, 0)
            quatf physics:localRot1 = (1, 0, 0, 0)
            float physics:lowerLimit = -89.999985
            float physics:upperLimit = 20.000008
            custom float urdf:dynamics:damping = 10
            custom float urdf:dynamics:friction = 0
            custom float urdf:limit:effort = 100
            custom float urdf:limit:velocity = 100
        }

        def PhysicsRevoluteJoint "rl4_joint" (
            prepend apiSchemas = ["PhysicsDriveAPI:angular", "PhysicsJointStateAPI:angular"]
        )
        {
            float drive:angular:physics:damping = 10
            float drive:angular:physics:maxForce = 100
            uniform token physics:axis = "Y"
            custom rel physics:body0
            prepend rel physics:body0 = </humanoid_urdf/Geometry/base_link/rl1_1/rl2_1/rl3_1/rl4_1>
            custom rel physics:body1
            prepend rel physics:body1 = </humanoid_urdf/Geometry/base_link/rl1_1/rl2_1/rl3_1/rl4_1/rl5_1>
            point3f physics:localPos0 = (0, 0, -0.092486)
            point3f physics:localPos1 = (0, 0, 0)
            quatf physics:localRot0 = (-0, -1, 0, 0)
            quatf physics:localRot1 = (-0, -1, 0, 0)
            float physics:lowerLimit = -20.000008
            float physics:upperLimit = 89.999985
            custom float urdf:dynamics:damping = 10
            custom float urdf:dynamics:friction = 0
            custom float urdf:limit:effort = 100
            custom float urdf:limit:velocity = 100
        }

        def PhysicsRevoluteJoint "rshd_yaw_joint" (
            prepend apiSchemas = ["PhysicsDriveAPI:angular", "PhysicsJointStateAPI:angular"]
        )
        {
            float drive:angular:physics:damping = 10
            float drive:angular:physics:maxForce = 100
            uniform token physics:axis = "X"
            custom rel physics:body0
            prepend rel physics:body0 = </humanoid_urdf/Geometry/base_link/rshd_pitch_1>
            custom rel physics:body1
            prepend rel physics:body1 = </humanoid_urdf/Geometry/base_link/rshd_pitch_1/rshd_2xl_1>
            point3f physics:localPos0 = (-0.019, -0.027, 0)
            point3f physics:localPos1 = (0, 0, 0)
            quatf physics:localRot0 = (1, 0, 0, 0)
            quatf physics:localRot1 = (1, 0, 0, 0)
            float physics:lowerLimit = -20.000008
            float physics:upperLimit = 89.999985
            custom float urdf:dynamics:damping = 10
            custom float urdf:dynamics:friction = 0
            custom float urdf:limit:effort = 100
            custom float urdf:limit:velocity = 100
        }

        def PhysicsFixedJoint "root_joint"
        {
            custom rel physics:body0
            prepend rel physics:body0 = </humanoid_urdf>
            custom rel physics:body1
            prepend rel physics:body1 = </humanoid_urdf/Geometry/base_link>
            point3f physics:localPos0 = (0, 0, 0)
            point3f physics:localPos1 = (0, 0, 0)
            quatf physics:localRot0 = (1, 0, 0, 0)
            quatf physics:localRot1 = (1, 0, 0, 0)
        }
    }
}

