<?xml version="1.0" ?>
<robot name="humanoid_urdf">

<!-- <xacro:include filename="$(find humanoid_urdf_description)/urdf/materials.xacro" />
<xacro:include filename="$(find humanoid_urdf_description)/urdf/humanoid_urdf.trans" />
<xacro:include filename="$(find humanoid_urdf_description)/urdf/humanoid_urdf.gazebo" /> -->


<material name="silver">
  <color rgba="0.700 0.700 0.700 1.000"/>
</material>


<transmission name="lgripper_joint_tran">
  <type>transmission_interface/SimpleTransmission</type>
  <joint name="lgripper_joint">
    <hardwareInterface>hardware_interface/EffortJointInterface</hardwareInterface>
  </joint>
  <actuator name="lgripper_joint_actr">
    <hardwareInterface>hardware_interface/EffortJointInterface</hardwareInterface>
    <mechanicalReduction>1</mechanicalReduction>
  </actuator>
</transmission>

<transmission name="lgrip_fin2_slider_tran">
  <type>transmission_interface/SimpleTransmission</type>
  <joint name="lgrip_fin2_slider">
    <hardwareInterface>hardware_interface/EffortJointInterface</hardwareInterface>
  </joint>
  <actuator name="lgrip_fin2_slider_actr">
    <hardwareInterface>hardware_interface/EffortJointInterface</hardwareInterface>
    <mechanicalReduction>1</mechanicalReduction>
  </actuator>
</transmission>

<transmission name="lgrip_fin1_slider_tran">
  <type>transmission_interface/SimpleTransmission</type>
  <joint name="lgrip_fin1_slider">
    <hardwareInterface>hardware_interface/EffortJointInterface</hardwareInterface>
  </joint>
  <actuator name="lgrip_fin1_slider_actr">
    <hardwareInterface>hardware_interface/EffortJointInterface</hardwareInterface>
    <mechanicalReduction>1</mechanicalReduction>
  </actuator>
</transmission>

<transmission name="lshd_yaw_joint_tran">
  <type>transmission_interface/SimpleTransmission</type>
  <joint name="lshd_yaw_joint">
    <hardwareInterface>hardware_interface/EffortJointInterface</hardwareInterface>
  </joint>
  <actuator name="lshd_yaw_joint_actr">
    <hardwareInterface>hardware_interface/EffortJointInterface</hardwareInterface>
    <mechanicalReduction>1</mechanicalReduction>
  </actuator>
</transmission>

<transmission name="lwrist_pitch_joint_tran">
  <type>transmission_interface/SimpleTransmission</type>
  <joint name="lwrist_pitch_joint">
    <hardwareInterface>hardware_interface/EffortJointInterface</hardwareInterface>
  </joint>
  <actuator name="lwrist_pitch_joint_actr">
    <hardwareInterface>hardware_interface/EffortJointInterface</hardwareInterface>
    <mechanicalReduction>1</mechanicalReduction>
  </actuator>
</transmission>

<transmission name="lwrist_yaw_joint_tran">
  <type>transmission_interface/SimpleTransmission</type>
  <joint name="lwrist_yaw_joint">
    <hardwareInterface>hardware_interface/EffortJointInterface</hardwareInterface>
  </joint>
  <actuator name="lwrist_yaw_joint_actr">
    <hardwareInterface>hardware_interface/EffortJointInterface</hardwareInterface>
    <mechanicalReduction>1</mechanicalReduction>
  </actuator>
</transmission>

<transmission name="rwrist_pitch_joint_tran">
  <type>transmission_interface/SimpleTransmission</type>
  <joint name="rwrist_pitch_joint">
    <hardwareInterface>hardware_interface/EffortJointInterface</hardwareInterface>
  </joint>
  <actuator name="rwrist_pitch_joint_actr">
    <hardwareInterface>hardware_interface/EffortJointInterface</hardwareInterface>
    <mechanicalReduction>1</mechanicalReduction>
  </actuator>
</transmission>

<transmission name="rwrist_yaw_joint_tran">
  <type>transmission_interface/SimpleTransmission</type>
  <joint name="rwrist_yaw_joint">
    <hardwareInterface>hardware_interface/EffortJointInterface</hardwareInterface>
  </joint>
  <actuator name="rwrist_yaw_joint_actr">
    <hardwareInterface>hardware_interface/EffortJointInterface</hardwareInterface>
    <mechanicalReduction>1</mechanicalReduction>
  </actuator>
</transmission>

<transmission name="rgripper_joint_tran">
  <type>transmission_interface/SimpleTransmission</type>
  <joint name="rgripper_joint">
    <hardwareInterface>hardware_interface/EffortJointInterface</hardwareInterface>
  </joint>
  <actuator name="rgripper_joint_actr">
    <hardwareInterface>hardware_interface/EffortJointInterface</hardwareInterface>
    <mechanicalReduction>1</mechanicalReduction>
  </actuator>
</transmission>

<transmission name="rgrip_fin1_slider_tran">
  <type>transmission_interface/SimpleTransmission</type>
  <joint name="rgrip_fin1_slider">
    <hardwareInterface>hardware_interface/EffortJointInterface</hardwareInterface>
  </joint>
  <actuator name="rgrip_fin1_slider_actr">
    <hardwareInterface>hardware_interface/EffortJointInterface</hardwareInterface>
    <mechanicalReduction>1</mechanicalReduction>
  </actuator>
</transmission>

<transmission name="rgrip_fin2_slider_tran">
  <type>transmission_interface/SimpleTransmission</type>
  <joint name="rgrip_fin2_slider">
    <hardwareInterface>hardware_interface/EffortJointInterface</hardwareInterface>
  </joint>
  <actuator name="rgrip_fin2_slider_actr">
    <hardwareInterface>hardware_interface/EffortJointInterface</hardwareInterface>
    <mechanicalReduction>1</mechanicalReduction>
  </actuator>
</transmission>

<transmission name="rshd_pitch_joint_tran">
  <type>transmission_interface/SimpleTransmission</type>
  <joint name="rshd_pitch_joint">
    <hardwareInterface>hardware_interface/EffortJointInterface</hardwareInterface>
  </joint>
  <actuator name="rshd_pitch_joint_actr">
    <hardwareInterface>hardware_interface/EffortJointInterface</hardwareInterface>
    <mechanicalReduction>1</mechanicalReduction>
  </actuator>
</transmission>

<transmission name="lshd_pitch_joint_tran">
  <type>transmission_interface/SimpleTransmission</type>
  <joint name="lshd_pitch_joint">
    <hardwareInterface>hardware_interface/EffortJointInterface</hardwareInterface>
  </joint>
  <actuator name="lshd_pitch_joint_actr">
    <hardwareInterface>hardware_interface/EffortJointInterface</hardwareInterface>
    <mechanicalReduction>1</mechanicalReduction>
  </actuator>
</transmission>

<transmission name="neck_roll_joint_tran">
  <type>transmission_interface/SimpleTransmission</type>
  <joint name="neck_roll_joint">
    <hardwareInterface>hardware_interface/EffortJointInterface</hardwareInterface>
  </joint>
  <actuator name="neck_roll_joint_actr">
    <hardwareInterface>hardware_interface/EffortJointInterface</hardwareInterface>
    <mechanicalReduction>1</mechanicalReduction>
  </actuator>
</transmission>

<transmission name="neck_pitch_joint_tran">
  <type>transmission_interface/SimpleTransmission</type>
  <joint name="neck_pitch_joint">
    <hardwareInterface>hardware_interface/EffortJointInterface</hardwareInterface>
  </joint>
  <actuator name="neck_pitch_joint_actr">
    <hardwareInterface>hardware_interface/EffortJointInterface</hardwareInterface>
    <mechanicalReduction>1</mechanicalReduction>
  </actuator>
</transmission>

<transmission name="lbase_joint_tran">
  <type>transmission_interface/SimpleTransmission</type>
  <joint name="lbase_joint">
    <hardwareInterface>hardware_interface/EffortJointInterface</hardwareInterface>
  </joint>
  <actuator name="lbase_joint_actr">
    <hardwareInterface>hardware_interface/EffortJointInterface</hardwareInterface>
    <mechanicalReduction>1</mechanicalReduction>
  </actuator>
</transmission>

<transmission name="ll1_joint_tran">
  <type>transmission_interface/SimpleTransmission</type>
  <joint name="ll1_joint">
    <hardwareInterface>hardware_interface/EffortJointInterface</hardwareInterface>
  </joint>
  <actuator name="ll1_joint_actr">
    <hardwareInterface>hardware_interface/EffortJointInterface</hardwareInterface>
    <mechanicalReduction>1</mechanicalReduction>
  </actuator>
</transmission>

<transmission name="rbase_joint_tran">
  <type>transmission_interface/SimpleTransmission</type>
  <joint name="rbase_joint">
    <hardwareInterface>hardware_interface/EffortJointInterface</hardwareInterface>
  </joint>
  <actuator name="rbase_joint_actr">
    <hardwareInterface>hardware_interface/EffortJointInterface</hardwareInterface>
    <mechanicalReduction>1</mechanicalReduction>
  </actuator>
</transmission>

<transmission name="rl3_joint_tran">
  <type>transmission_interface/SimpleTransmission</type>
  <joint name="rl3_joint">
    <hardwareInterface>hardware_interface/EffortJointInterface</hardwareInterface>
  </joint>
  <actuator name="rl3_joint_actr">
    <hardwareInterface>hardware_interface/EffortJointInterface</hardwareInterface>
    <mechanicalReduction>1</mechanicalReduction>
  </actuator>
</transmission>

<transmission name="rl5_joint_tran">
  <type>transmission_interface/SimpleTransmission</type>
  <joint name="rl5_joint">
    <hardwareInterface>hardware_interface/EffortJointInterface</hardwareInterface>
  </joint>
  <actuator name="rl5_joint_actr">
    <hardwareInterface>hardware_interface/EffortJointInterface</hardwareInterface>
    <mechanicalReduction>1</mechanicalReduction>
  </actuator>
</transmission>

<transmission name="ll2_joint_tran">
  <type>transmission_interface/SimpleTransmission</type>
  <joint name="ll2_joint">
    <hardwareInterface>hardware_interface/EffortJointInterface</hardwareInterface>
  </joint>
  <actuator name="ll2_joint_actr">
    <hardwareInterface>hardware_interface/EffortJointInterface</hardwareInterface>
    <mechanicalReduction>1</mechanicalReduction>
  </actuator>
</transmission>

<transmission name="ll3_joint_tran">
  <type>transmission_interface/SimpleTransmission</type>
  <joint name="ll3_joint">
    <hardwareInterface>hardware_interface/EffortJointInterface</hardwareInterface>
  </joint>
  <actuator name="ll3_joint_actr">
    <hardwareInterface>hardware_interface/EffortJointInterface</hardwareInterface>
    <mechanicalReduction>1</mechanicalReduction>
  </actuator>
</transmission>

<transmission name="ll5_joint_tran">
  <type>transmission_interface/SimpleTransmission</type>
  <joint name="ll5_joint">
    <hardwareInterface>hardware_interface/EffortJointInterface</hardwareInterface>
  </joint>
  <actuator name="ll5_joint_actr">
    <hardwareInterface>hardware_interface/EffortJointInterface</hardwareInterface>
    <mechanicalReduction>1</mechanicalReduction>
  </actuator>
</transmission>

<transmission name="rl1_joint_tran">
  <type>transmission_interface/SimpleTransmission</type>
  <joint name="rl1_joint">
    <hardwareInterface>hardware_interface/EffortJointInterface</hardwareInterface>
  </joint>
  <actuator name="rl1_joint_actr">
    <hardwareInterface>hardware_interface/EffortJointInterface</hardwareInterface>
    <mechanicalReduction>1</mechanicalReduction>
  </actuator>
</transmission>

<transmission name="rl2_joint_tran">
  <type>transmission_interface/SimpleTransmission</type>
  <joint name="rl2_joint">
    <hardwareInterface>hardware_interface/EffortJointInterface</hardwareInterface>
  </joint>
  <actuator name="rl2_joint_actr">
    <hardwareInterface>hardware_interface/EffortJointInterface</hardwareInterface>
    <mechanicalReduction>1</mechanicalReduction>
  </actuator>
</transmission>

<transmission name="lshd_roll_joint_tran">
  <type>transmission_interface/SimpleTransmission</type>
  <joint name="lshd_roll_joint">
    <hardwareInterface>hardware_interface/EffortJointInterface</hardwareInterface>
  </joint>
  <actuator name="lshd_roll_joint_actr">
    <hardwareInterface>hardware_interface/EffortJointInterface</hardwareInterface>
    <mechanicalReduction>1</mechanicalReduction>
  </actuator>
</transmission>

<transmission name="lelbow_joint_tran">
  <type>transmission_interface/SimpleTransmission</type>
  <joint name="lelbow_joint">
    <hardwareInterface>hardware_interface/EffortJointInterface</hardwareInterface>
  </joint>
  <actuator name="lelbow_joint_actr">
    <hardwareInterface>hardware_interface/EffortJointInterface</hardwareInterface>
    <mechanicalReduction>1</mechanicalReduction>
  </actuator>
</transmission>

<transmission name="rshd_roll_joint_tran">
  <type>transmission_interface/SimpleTransmission</type>
  <joint name="rshd_roll_joint">
    <hardwareInterface>hardware_interface/EffortJointInterface</hardwareInterface>
  </joint>
  <actuator name="rshd_roll_joint_actr">
    <hardwareInterface>hardware_interface/EffortJointInterface</hardwareInterface>
    <mechanicalReduction>1</mechanicalReduction>
  </actuator>
</transmission>

<transmission name="relbow_joint_tran">
  <type>transmission_interface/SimpleTransmission</type>
  <joint name="relbow_joint">
    <hardwareInterface>hardware_interface/EffortJointInterface</hardwareInterface>
  </joint>
  <actuator name="relbow_joint_actr">
    <hardwareInterface>hardware_interface/EffortJointInterface</hardwareInterface>
    <mechanicalReduction>1</mechanicalReduction>
  </actuator>
</transmission>

<transmission name="ll4_joint_tran">
  <type>transmission_interface/SimpleTransmission</type>
  <joint name="ll4_joint">
    <hardwareInterface>hardware_interface/EffortJointInterface</hardwareInterface>
  </joint>
  <actuator name="ll4_joint_actr">
    <hardwareInterface>hardware_interface/EffortJointInterface</hardwareInterface>
    <mechanicalReduction>1</mechanicalReduction>
  </actuator>
</transmission>

<transmission name="rl4_joint_tran">
  <type>transmission_interface/SimpleTransmission</type>
  <joint name="rl4_joint">
    <hardwareInterface>hardware_interface/EffortJointInterface</hardwareInterface>
  </joint>
  <actuator name="rl4_joint_actr">
    <hardwareInterface>hardware_interface/EffortJointInterface</hardwareInterface>
    <mechanicalReduction>1</mechanicalReduction>
  </actuator>
</transmission>

<transmission name="rshd_yaw_joint_tran">
  <type>transmission_interface/SimpleTransmission</type>
  <joint name="rshd_yaw_joint">
    <hardwareInterface>hardware_interface/EffortJointInterface</hardwareInterface>
  </joint>
  <actuator name="rshd_yaw_joint_actr">
    <hardwareInterface>hardware_interface/EffortJointInterface</hardwareInterface>
    <mechanicalReduction>1</mechanicalReduction>
  </actuator>
</transmission>



<link name="base_link">
  <inertial>
    <origin xyz="-0.005799007929849412 -0.0019422579747158052 0.3350890323845471" rpy="0 0 0"/>
    <mass value="0.6659240922979891"/>
    <inertia ixx="0.004009" iyy="0.002884" izz="0.003201" ixy="-0.0" iyz="-0.0" ixz="-0.000144"/>
  </inertial>
  <visual>
    <origin xyz="0 0 0" rpy="0 0 0"/>
    <geometry>
      <mesh filename="package://humanoid_urdf_description/meshes/base_link.stl" scale="0.001 0.001 0.001"/>
    </geometry>
    <material name="silver"/>
  </visual>
  <collision>
    <origin xyz="0 0 0" rpy="0 0 0"/>
    <geometry>
      <mesh filename="package://humanoid_urdf_description/meshes/base_link.stl" scale="0.001 0.001 0.001"/>
    </geometry>
  </collision>
</link>

<link name="lgrip_gear_1">
  <inertial>
    <origin xyz="-2.2601354432438825e-07 0.0025174014361563635 -1.5543648107518848e-07" rpy="0 0 0"/>
    <mass value="0.002515348048999408"/>
    <inertia ixx="1e-06" iyy="1e-06" izz="1e-06" ixy="-0.0" iyz="0.0" ixz="-0.0"/>
  </inertial>
  <visual>
    <origin xyz="-0.018924 -0.316806 -0.379216" rpy="0 0 0"/>
    <geometry>
      <mesh filename="package://humanoid_urdf_description/meshes/lgrip_gear_1.stl" scale="0.001 0.001 0.001"/>
    </geometry>
    <material name="silver"/>
  </visual>
  <collision>
    <origin xyz="-0.018924 -0.316806 -0.379216" rpy="0 0 0"/>
    <geometry>
      <mesh filename="package://humanoid_urdf_description/meshes/lgrip_gear_1.stl" scale="0.001 0.001 0.001"/>
    </geometry>
  </collision>
</link>

<link name="lgrip_fin2_1">
  <inertial>
    <origin xyz="0.015181617337629249 0.03868576288307052 0.019122628822199395" rpy="0 0 0"/>
    <mass value="0.03333747674318192"/>
    <inertia ixx="1.6e-05" iyy="7e-06" izz="1.3e-05" ixy="0.0" iyz="0.0" ixz="0.0"/>
  </inertial>
  <visual>
    <origin xyz="-0.018924 -0.316006 -0.360016" rpy="0 0 0"/>
    <geometry>
      <mesh filename="package://humanoid_urdf_description/meshes/lgrip_fin2_1.stl" scale="0.001 0.001 0.001"/>
    </geometry>
    <material name="silver"/>
  </visual>
  <collision>
    <origin xyz="-0.018924 -0.316006 -0.360016" rpy="0 0 0"/>
    <geometry>
      <mesh filename="package://humanoid_urdf_description/meshes/lgrip_fin2_1.stl" scale="0.001 0.001 0.001"/>
    </geometry>
  </collision>
</link>

<link name="lgrip_fin1_1">
  <inertial>
    <origin xyz="-0.015181918559323078 0.03868576288306286 -0.019122939695159213" rpy="0 0 0"/>
    <mass value="0.03333747674318192"/>
    <inertia ixx="1.6e-05" iyy="7e-06" izz="1.3e-05" ixy="-0.0" iyz="-0.0" ixz="0.0"/>
  </inertial>
  <visual>
    <origin xyz="-0.018831 -0.316006 -0.398416" rpy="0 0 0"/>
    <geometry>
      <mesh filename="package://humanoid_urdf_description/meshes/lgrip_fin1_1.stl" scale="0.001 0.001 0.001"/>
    </geometry>
    <material name="silver"/>
  </visual>
  <collision>
    <origin xyz="-0.018831 -0.316006 -0.398416" rpy="0 0 0"/>
    <geometry>
      <mesh filename="package://humanoid_urdf_description/meshes/lgrip_fin1_1.stl" scale="0.001 0.001 0.001"/>
    </geometry>
  </collision>
</link>

<link name="lshd_2xl_1">
  <inertial>
    <origin xyz="0.01821386883633947 0.004735041880164534 0.011929063948829088" rpy="0 0 0"/>
    <mass value="0.08476710413561503"/>
    <inertia ixx="2.8e-05" iyy="2.3e-05" izz="2.2e-05" ixy="-1e-06" iyz="-0.0" ixz="-0.0"/>
  </inertial>
  <visual>
    <origin xyz="7.6e-05 -0.107206 -0.381916" rpy="0 0 0"/>
    <geometry>
      <mesh filename="package://humanoid_urdf_description/meshes/lshd_2xl_1.stl" scale="0.001 0.001 0.001"/>
    </geometry>
    <material name="silver"/>
  </visual>
  <collision>
    <origin xyz="7.6e-05 -0.107206 -0.381916" rpy="0 0 0"/>
    <geometry>
      <mesh filename="package://humanoid_urdf_description/meshes/lshd_2xl_1.stl" scale="0.001 0.001 0.001"/>
    </geometry>
  </collision>
</link>

<link name="lwrist_1">
  <inertial>
    <origin xyz="-0.0007578337003172897 -0.0114192445318681 -0.026135356324180625" rpy="0 0 0"/>
    <mass value="0.08793324627970979"/>
    <inertia ixx="3e-05" iyy="2.4e-05" izz="2.4e-05" ixy="0.0" iyz="0.0" ixz="-1e-06"/>
  </inertial>
  <visual>
    <origin xyz="-0.018924 -0.277106 -0.407916" rpy="0 0 0"/>
    <geometry>
      <mesh filename="package://humanoid_urdf_description/meshes/lwrist_1.stl" scale="0.001 0.001 0.001"/>
    </geometry>
    <material name="silver"/>
  </visual>
  <collision>
    <origin xyz="-0.018924 -0.277106 -0.407916" rpy="0 0 0"/>
    <geometry>
      <mesh filename="package://humanoid_urdf_description/meshes/lwrist_1.stl" scale="0.001 0.001 0.001"/>
    </geometry>
  </collision>
</link>

<link name="lgripper_1">
  <inertial>
    <origin xyz="0.010330923951847534 0.02723895972842466 0.0029692931888307683" rpy="0 0 0"/>
    <mass value="0.07577726651931928"/>
    <inertia ixx="3.3e-05" iyy="6.7e-05" izz="7.9e-05" ixy="2e-06" iyz="1e-06" ixz="6e-06"/>
  </inertial>
  <visual>
    <origin xyz="7.6e-05 -0.277106 -0.379216" rpy="0 0 0"/>
    <geometry>
      <mesh filename="package://humanoid_urdf_description/meshes/lgripper_1.stl" scale="0.001 0.001 0.001"/>
    </geometry>
    <material name="silver"/>
  </visual>
  <collision>
    <origin xyz="7.6e-05 -0.277106 -0.379216" rpy="0 0 0"/>
    <geometry>
      <mesh filename="package://humanoid_urdf_description/meshes/lgripper_1.stl" scale="0.001 0.001 0.001"/>
    </geometry>
  </collision>
</link>

<link name="rwrist_1">
  <inertial>
    <origin xyz="0.0007573816822770661 0.011419834584302568 -0.026135356393195752" rpy="0 0 0"/>
    <mass value="0.08793324627970973"/>
    <inertia ixx="3e-05" iyy="2.4e-05" izz="2.4e-05" ixy="0.0" iyz="-0.0" ixz="1e-06"/>
  </inertial>
  <visual>
    <origin xyz="-0.017924 0.280904 -0.407916" rpy="0 0 0"/>
    <geometry>
      <mesh filename="package://humanoid_urdf_description/meshes/rwrist_1.stl" scale="0.001 0.001 0.001"/>
    </geometry>
    <material name="silver"/>
  </visual>
  <collision>
    <origin xyz="-0.017924 0.280904 -0.407916" rpy="0 0 0"/>
    <geometry>
      <mesh filename="package://humanoid_urdf_description/meshes/rwrist_1.stl" scale="0.001 0.001 0.001"/>
    </geometry>
  </collision>
</link>

<link name="rgripper_1">
  <inertial>
    <origin xyz="-0.027675786426083246 -0.027238369666215956 0.0030303528673583102" rpy="0 0 0"/>
    <mass value="0.07577726656267422"/>
    <inertia ixx="3.3e-05" iyy="6.7e-05" izz="8e-05" ixy="-2e-06" iyz="-0.0" ixz="6e-06"/>
  </inertial>
  <visual>
    <origin xyz="-0.036924 0.280904 -0.379216" rpy="0 0 0"/>
    <geometry>
      <mesh filename="package://humanoid_urdf_description/meshes/rgripper_1.stl" scale="0.001 0.001 0.001"/>
    </geometry>
    <material name="silver"/>
  </visual>
  <collision>
    <origin xyz="-0.036924 0.280904 -0.379216" rpy="0 0 0"/>
    <geometry>
      <mesh filename="package://humanoid_urdf_description/meshes/rgripper_1.stl" scale="0.001 0.001 0.001"/>
    </geometry>
  </collision>
</link>

<link name="rgrip_gear_1">
  <inertial>
    <origin xyz="-2.2601348083697848e-07 -0.002516811383721951 -1.5579455969749745e-07" rpy="0 0 0"/>
    <mass value="0.002515348048999408"/>
    <inertia ixx="1e-06" iyy="1e-06" izz="1e-06" ixy="-0.0" iyz="0.0" ixz="0.0"/>
  </inertial>
  <visual>
    <origin xyz="-0.017924 0.320604 -0.379216" rpy="0 0 0"/>
    <geometry>
      <mesh filename="package://humanoid_urdf_description/meshes/rgrip_gear_1.stl" scale="0.001 0.001 0.001"/>
    </geometry>
    <material name="silver"/>
  </visual>
  <collision>
    <origin xyz="-0.017924 0.320604 -0.379216" rpy="0 0 0"/>
    <geometry>
      <mesh filename="package://humanoid_urdf_description/meshes/rgrip_gear_1.stl" scale="0.001 0.001 0.001"/>
    </geometry>
  </collision>
</link>

<link name="rgrip_fin1_1">
  <inertial>
    <origin xyz="-0.015182069364654336 -0.038685172830636216 0.019122628464117664" rpy="0 0 0"/>
    <mass value="0.03333747674318192"/>
    <inertia ixx="1.6e-05" iyy="7e-06" izz="1.3e-05" ixy="0.0" iyz="-0.0" ixz="-0.0"/>
  </inertial>
  <visual>
    <origin xyz="-0.017924 0.319804 -0.360016" rpy="0 0 0"/>
    <geometry>
      <mesh filename="package://humanoid_urdf_description/meshes/rgrip_fin1_1.stl" scale="0.001 0.001 0.001"/>
    </geometry>
    <material name="silver"/>
  </visual>
  <collision>
    <origin xyz="-0.017924 0.319804 -0.360016" rpy="0 0 0"/>
    <geometry>
      <mesh filename="package://humanoid_urdf_description/meshes/rgrip_fin1_1.stl" scale="0.001 0.001 0.001"/>
    </geometry>
  </collision>
</link>

<link name="rgrip_fin2_1">
  <inertial>
    <origin xyz="0.01518176814312406 -0.038685172830628334 -0.01912294005323717" rpy="0 0 0"/>
    <mass value="0.03333747674318192"/>
    <inertia ixx="1.6e-05" iyy="7e-06" izz="1.3e-05" ixy="-0.0" iyz="0.0" ixz="-0.0"/>
  </inertial>
  <visual>
    <origin xyz="-0.017831 0.319804 -0.398416" rpy="0 0 0"/>
    <geometry>
      <mesh filename="package://humanoid_urdf_description/meshes/rgrip_fin2_1.stl" scale="0.001 0.001 0.001"/>
    </geometry>
    <material name="silver"/>
  </visual>
  <collision>
    <origin xyz="-0.017831 0.319804 -0.398416" rpy="0 0 0"/>
    <geometry>
      <mesh filename="package://humanoid_urdf_description/meshes/rgrip_fin2_1.stl" scale="0.001 0.001 0.001"/>
    </geometry>
  </collision>
</link>

<link name="rshd_pitch_1">
  <inertial>
    <origin xyz="-2.2601349694909012e-07 -0.012912922526919862 -1.5564210659180233e-07" rpy="0 0 0"/>
    <mass value="0.0157117409033363"/>
    <inertia ixx="3e-06" iyy="6e-06" izz="7e-06" ixy="-0.0" iyz="0.0" ixz="-0.0"/>
  </inertial>
  <visual>
    <origin xyz="-0.018924 0.084004 -0.381916" rpy="0 0 0"/>
    <geometry>
      <mesh filename="package://humanoid_urdf_description/meshes/rshd_pitch_1.stl" scale="0.001 0.001 0.001"/>
    </geometry>
    <material name="silver"/>
  </visual>
  <collision>
    <origin xyz="-0.018924 0.084004 -0.381916" rpy="0 0 0"/>
    <geometry>
      <mesh filename="package://humanoid_urdf_description/meshes/rshd_pitch_1.stl" scale="0.001 0.001 0.001"/>
    </geometry>
  </collision>
</link>

<link name="lshd_pitch_1">
  <inertial>
    <origin xyz="-2.2601352955842202e-07 0.01291351242690654 -1.5564210747998075e-07" rpy="0 0 0"/>
    <mass value="0.0157117409033363"/>
    <inertia ixx="3e-06" iyy="6e-06" izz="7e-06" ixy="-0.0" iyz="-0.0" ixz="0.0"/>
  </inertial>
  <visual>
    <origin xyz="-0.018924 -0.080206 -0.381916" rpy="0 0 0"/>
    <geometry>
      <mesh filename="package://humanoid_urdf_description/meshes/lshd_pitch_1.stl" scale="0.001 0.001 0.001"/>
    </geometry>
    <material name="silver"/>
  </visual>
  <collision>
    <origin xyz="-0.018924 -0.080206 -0.381916" rpy="0 0 0"/>
    <geometry>
      <mesh filename="package://humanoid_urdf_description/meshes/lshd_pitch_1.stl" scale="0.001 0.001 0.001"/>
    </geometry>
  </collision>
</link>

<link name="neck_1">
  <inertial>
    <origin xyz="-5.8993040728053114e-06 0.0005056988631585504 0.00783028892749299" rpy="0 0 0"/>
    <mass value="0.005062828410877468"/>
    <inertia ixx="1e-06" iyy="1e-06" izz="1e-06" ixy="-0.0" iyz="0.0" ixz="0.0"/>
  </inertial>
  <visual>
    <origin xyz="-0.009136 0.002011 -0.419533" rpy="0 0 0"/>
    <geometry>
      <mesh filename="package://humanoid_urdf_description/meshes/neck_1.stl" scale="0.001 0.001 0.001"/>
    </geometry>
    <material name="silver"/>
  </visual>
  <collision>
    <origin xyz="-0.009136 0.002011 -0.419533" rpy="0 0 0"/>
    <geometry>
      <mesh filename="package://humanoid_urdf_description/meshes/neck_1.stl" scale="0.001 0.001 0.001"/>
    </geometry>
  </collision>
</link>

<link name="head_1">
  <inertial>
    <origin xyz="0.00334478594326635 0.014060597301845282 0.01845971527487761" rpy="0 0 0"/>
    <mass value="0.031003182579640465"/>
    <inertia ixx="1.2e-05" iyy="1.3e-05" izz="4e-06" ixy="-0.0" iyz="-0.0" ixz="-3e-06"/>
  </inertial>
  <visual>
    <origin xyz="-0.009045 0.016057 -0.438099" rpy="0 0 0"/>
    <geometry>
      <mesh filename="package://humanoid_urdf_description/meshes/head_1.stl" scale="0.001 0.001 0.001"/>
    </geometry>
    <material name="silver"/>
  </visual>
  <collision>
    <origin xyz="-0.009045 0.016057 -0.438099" rpy="0 0 0"/>
    <geometry>
      <mesh filename="package://humanoid_urdf_description/meshes/head_1.stl" scale="0.001 0.001 0.001"/>
    </geometry>
  </collision>
</link>

<link name="ll1_1">
  <inertial>
    <origin xyz="-0.000324868161245464 2.5123219721256973e-07 -0.01537395502683428" rpy="0 0 0"/>
    <mass value="0.012917415150155305"/>
    <inertia ixx="2e-06" iyy="8e-06" izz="7e-06" ixy="-0.0" iyz="0.0" ixz="-0.0"/>
  </inertial>
  <visual>
    <origin xyz="-0.001007 -0.05803 -0.258033" rpy="0 0 0"/>
    <geometry>
      <mesh filename="package://humanoid_urdf_description/meshes/ll1_1.stl" scale="0.001 0.001 0.001"/>
    </geometry>
    <material name="silver"/>
  </visual>
  <collision>
    <origin xyz="-0.001007 -0.05803 -0.258033" rpy="0 0 0"/>
    <geometry>
      <mesh filename="package://humanoid_urdf_description/meshes/ll1_1.stl" scale="0.001 0.001 0.001"/>
    </geometry>
  </collision>
</link>

<link name="ll2_1">
  <inertial>
    <origin xyz="-0.04091824568283125 0.00024752093223290306 -0.01215740264201931" rpy="0 0 0"/>
    <mass value="0.13078226931984757"/>
    <inertia ixx="3.4e-05" iyy="0.000105" izz="9.4e-05" ixy="-1e-06" iyz="-0.0" ixz="-0.0"/>
  </inertial>
  <visual>
    <origin xyz="-0.021427 -0.05803 -0.223533" rpy="0 0 0"/>
    <geometry>
      <mesh filename="package://humanoid_urdf_description/meshes/ll2_1.stl" scale="0.001 0.001 0.001"/>
    </geometry>
    <material name="silver"/>
  </visual>
  <collision>
    <origin xyz="-0.021427 -0.05803 -0.223533" rpy="0 0 0"/>
    <geometry>
      <mesh filename="package://humanoid_urdf_description/meshes/ll2_1.stl" scale="0.001 0.001 0.001"/>
    </geometry>
  </collision>
</link>

<link name="rl1_1">
  <inertial>
    <origin xyz="-0.00032486816124601466 2.512321968101139e-07 -0.01537395502237704" rpy="0 0 0"/>
    <mass value="0.01291741515015535"/>
    <inertia ixx="2e-06" iyy="8e-06" izz="7e-06" ixy="-0.0" iyz="0.0" ixz="-0.0"/>
  </inertial>
  <visual>
    <origin xyz="-0.001007 0.06197 -0.258033" rpy="0 0 0"/>
    <geometry>
      <mesh filename="package://humanoid_urdf_description/meshes/rl1_1.stl" scale="0.001 0.001 0.001"/>
    </geometry>
    <material name="silver"/>
  </visual>
  <collision>
    <origin xyz="-0.001007 0.06197 -0.258033" rpy="0 0 0"/>
    <geometry>
      <mesh filename="package://humanoid_urdf_description/meshes/rl1_1.stl" scale="0.001 0.001 0.001"/>
    </geometry>
  </collision>
</link>

<link name="rl4_1">
  <inertial>
    <origin xyz="-1.5621050886583526e-07 -0.020217643412060678 -0.046243227760864175" rpy="0 0 0"/>
    <mass value="0.022805605859881364"/>
    <inertia ixx="2.4e-05" iyy="1.7e-05" izz="9e-06" ixy="-0.0" iyz="0.0" ixz="0.0"/>
  </inertial>
  <visual>
    <origin xyz="-0.003177 0.04297 -0.131032" rpy="0 0 0"/>
    <geometry>
      <mesh filename="package://humanoid_urdf_description/meshes/rl4_1.stl" scale="0.001 0.001 0.001"/>
    </geometry>
    <material name="silver"/>
  </visual>
  <collision>
    <origin xyz="-0.003177 0.04297 -0.131032" rpy="0 0 0"/>
    <geometry>
      <mesh filename="package://humanoid_urdf_description/meshes/rl4_1.stl" scale="0.001 0.001 0.001"/>
    </geometry>
  </collision>
</link>

<link name="rl6_1">
  <inertial>
    <origin xyz="0.027462674832497574 -0.011389521836556699 -0.030839874026291004" rpy="0 0 0"/>
    <mass value="0.08571227124117571"/>
    <inertia ixx="6.5e-05" iyy="0.000162" izz="0.000221" ixy="-0.0" iyz="-2e-06" ixz="-1e-06"/>
  </inertial>
  <visual>
    <origin xyz="0.026062 0.06197 -0.038546" rpy="0 0 0"/>
    <geometry>
      <mesh filename="package://humanoid_urdf_description/meshes/rl6_1.stl" scale="0.001 0.001 0.001"/>
    </geometry>
    <material name="silver"/>
  </visual>
  <collision>
    <origin xyz="0.026062 0.06197 -0.038546" rpy="0 0 0"/>
    <geometry>
      <mesh filename="package://humanoid_urdf_description/meshes/rl6_1.stl" scale="0.001 0.001 0.001"/>
    </geometry>
  </collision>
</link>

<link name="ll3_1">
  <inertial>
    <origin xyz="-6.459476128334004e-05 0.019596398737445654 -0.06439679539985171" rpy="0 0 0"/>
    <mass value="0.07734223550377772"/>
    <inertia ixx="5.7e-05" iyy="5e-05" izz="1.7e-05" ixy="0.0" iyz="-1e-06" ixz="-0.0"/>
  </inertial>
  <visual>
    <origin xyz="-0.003177 -0.03903 -0.223525" rpy="0 0 0"/>
    <geometry>
      <mesh filename="package://humanoid_urdf_description/meshes/ll3_1.stl" scale="0.001 0.001 0.001"/>
    </geometry>
    <material name="silver"/>
  </visual>
  <collision>
    <origin xyz="-0.003177 -0.03903 -0.223525" rpy="0 0 0"/>
    <geometry>
      <mesh filename="package://humanoid_urdf_description/meshes/ll3_1.stl" scale="0.001 0.001 0.001"/>
    </geometry>
  </collision>
</link>

<link name="ll4_1">
  <inertial>
    <origin xyz="4.289020351052643e-07 0.020218097688314292 -0.04624264243578578" rpy="0 0 0"/>
    <mass value="0.02280560585988143"/>
    <inertia ixx="2.4e-05" iyy="1.7e-05" izz="9e-06" ixy="0.0" iyz="0.0" ixz="-0.0"/>
  </inertial>
  <visual>
    <origin xyz="-0.003112 -0.03903 -0.136231" rpy="0 0 0"/>
    <geometry>
      <mesh filename="package://humanoid_urdf_description/meshes/ll4_1.stl" scale="0.001 0.001 0.001"/>
    </geometry>
    <material name="silver"/>
  </visual>
  <collision>
    <origin xyz="-0.003112 -0.03903 -0.136231" rpy="0 0 0"/>
    <geometry>
      <mesh filename="package://humanoid_urdf_description/meshes/ll4_1.stl" scale="0.001 0.001 0.001"/>
    </geometry>
  </collision>
</link>

<link name="ll6_1">
  <inertial>
    <origin xyz="0.02746325994504503 0.011389976112803277 -0.030840273010610902" rpy="0 0 0"/>
    <mass value="0.08571227124117566"/>
    <inertia ixx="6.5e-05" iyy="0.000162" izz="0.000221" ixy="0.0" iyz="2e-06" ixz="-1e-06"/>
  </inertial>
  <visual>
    <origin xyz="0.026127 -0.05803 -0.043746" rpy="0 0 0"/>
    <geometry>
      <mesh filename="package://humanoid_urdf_description/meshes/ll6_1.stl" scale="0.001 0.001 0.001"/>
    </geometry>
    <material name="silver"/>
  </visual>
  <collision>
    <origin xyz="0.026127 -0.05803 -0.043746" rpy="0 0 0"/>
    <geometry>
      <mesh filename="package://humanoid_urdf_description/meshes/ll6_1.stl" scale="0.001 0.001 0.001"/>
    </geometry>
  </collision>
</link>

<link name="rl2_1">
  <inertial>
    <origin xyz="-0.0409182456828239 -0.00024523842877196417 -0.012157402642023613" rpy="0 0 0"/>
    <mass value="0.13078226931984804"/>
    <inertia ixx="3.4e-05" iyy="0.000105" izz="9.4e-05" ixy="1e-06" iyz="0.0" ixz="-0.0"/>
  </inertial>
  <visual>
    <origin xyz="-0.021427 0.06197 -0.223533" rpy="0 0 0"/>
    <geometry>
      <mesh filename="package://humanoid_urdf_description/meshes/rl2_1.stl" scale="0.001 0.001 0.001"/>
    </geometry>
    <material name="silver"/>
  </visual>
  <collision>
    <origin xyz="-0.021427 0.06197 -0.223533" rpy="0 0 0"/>
    <geometry>
      <mesh filename="package://humanoid_urdf_description/meshes/rl2_1.stl" scale="0.001 0.001 0.001"/>
    </geometry>
  </collision>
</link>

<link name="rl3_1">
  <inertial>
    <origin xyz="-1.798758521272606e-07 -0.019595944137411357 -0.06959639641496687" rpy="0 0 0"/>
    <mass value="0.07734223549835353"/>
    <inertia ixx="5.7e-05" iyy="5e-05" izz="1.7e-05" ixy="-0.0" iyz="1e-06" ixz="-0.0"/>
  </inertial>
  <visual>
    <origin xyz="-0.003177 0.04297 -0.223525" rpy="0 0 0"/>
    <geometry>
      <mesh filename="package://humanoid_urdf_description/meshes/rl3_1.stl" scale="0.001 0.001 0.001"/>
    </geometry>
    <material name="silver"/>
  </visual>
  <collision>
    <origin xyz="-0.003177 0.04297 -0.223525" rpy="0 0 0"/>
    <geometry>
      <mesh filename="package://humanoid_urdf_description/meshes/rl3_1.stl" scale="0.001 0.001 0.001"/>
    </geometry>
  </collision>
</link>

<link name="lshd_yaw_1">
  <inertial>
    <origin xyz="-2.303931278917204e-07 0.020294759695708903 -1.2973680074690463e-07" rpy="0 0 0"/>
    <mass value="0.016893673089971303"/>
    <inertia ixx="7e-06" iyy="5e-06" izz="4e-06" ixy="-0.0" iyz="0.0" ixz="-0.0"/>
  </inertial>
  <visual>
    <origin xyz="-0.018924 -0.133206 -0.381916" rpy="0 0 0"/>
    <geometry>
      <mesh filename="package://humanoid_urdf_description/meshes/lshd_yaw_1.stl" scale="0.001 0.001 0.001"/>
    </geometry>
    <material name="silver"/>
  </visual>
  <collision>
    <origin xyz="-0.018924 -0.133206 -0.381916" rpy="0 0 0"/>
    <geometry>
      <mesh filename="package://humanoid_urdf_description/meshes/lshd_yaw_1.stl" scale="0.001 0.001 0.001"/>
    </geometry>
  </collision>
</link>

<link name="lelbow_1">
  <inertial>
    <origin xyz="-2.259787635905397e-07 0.028605080405966404 0.018959702203030337" rpy="0 0 0"/>
    <mass value="0.08838540484513303"/>
    <inertia ixx="9.8e-05" iyy="3.2e-05" izz="7.6e-05" ixy="-0.0" iyz="-2e-06" ixz="0.0"/>
  </inertial>
  <visual>
    <origin xyz="-0.018924 -0.176906 -0.362916" rpy="0 0 0"/>
    <geometry>
      <mesh filename="package://humanoid_urdf_description/meshes/lelbow_1.stl" scale="0.001 0.001 0.001"/>
    </geometry>
    <material name="silver"/>
  </visual>
  <collision>
    <origin xyz="-0.018924 -0.176906 -0.362916" rpy="0 0 0"/>
    <geometry>
      <mesh filename="package://humanoid_urdf_description/meshes/lelbow_1.stl" scale="0.001 0.001 0.001"/>
    </geometry>
  </collision>
</link>

<link name="rshd_yaw_1">
  <inertial>
    <origin xyz="-2.2179481354647756e-07 -0.02029416854528368 -1.275364638897436e-07" rpy="0 0 0"/>
    <mass value="0.01689367308997018"/>
    <inertia ixx="7e-06" iyy="5e-06" izz="4e-06" ixy="-0.0" iyz="0.0" ixz="0.0"/>
  </inertial>
  <visual>
    <origin xyz="-0.017924 0.137004 -0.381916" rpy="0 0 0"/>
    <geometry>
      <mesh filename="package://humanoid_urdf_description/meshes/rshd_yaw_1.stl" scale="0.001 0.001 0.001"/>
    </geometry>
    <material name="silver"/>
  </visual>
  <collision>
    <origin xyz="-0.017924 0.137004 -0.381916" rpy="0 0 0"/>
    <geometry>
      <mesh filename="package://humanoid_urdf_description/meshes/rshd_yaw_1.stl" scale="0.001 0.001 0.001"/>
    </geometry>
  </collision>
</link>

<link name="relbow_1">
  <inertial>
    <origin xyz="-2.2604826054387073e-07 -0.02860449035352075 0.01895970184496676" rpy="0 0 0"/>
    <mass value="0.08838540484513334"/>
    <inertia ixx="9.8e-05" iyy="3.2e-05" izz="7.6e-05" ixy="-0.0" iyz="2e-06" ixz="-0.0"/>
  </inertial>
  <visual>
    <origin xyz="-0.017924 0.180704 -0.362916" rpy="0 0 0"/>
    <geometry>
      <mesh filename="package://humanoid_urdf_description/meshes/relbow_1.stl" scale="0.001 0.001 0.001"/>
    </geometry>
    <material name="silver"/>
  </visual>
  <collision>
    <origin xyz="-0.017924 0.180704 -0.362916" rpy="0 0 0"/>
    <geometry>
      <mesh filename="package://humanoid_urdf_description/meshes/relbow_1.stl" scale="0.001 0.001 0.001"/>
    </geometry>
  </collision>
</link>

<link name="ll5_1">
  <inertial>
    <origin xyz="-0.022667660570277647 0.019245692705025262 0.012148804951260625" rpy="0 0 0"/>
    <mass value="0.13078226931984807"/>
    <inertia ixx="3.4e-05" iyy="0.000105" izz="9.4e-05" ixy="-1e-06" iyz="0.0" ixz="0.0"/>
  </inertial>
  <visual>
    <origin xyz="-0.003112 -0.03903 -0.043746" rpy="0 0 0"/>
    <geometry>
      <mesh filename="package://humanoid_urdf_description/meshes/ll5_1.stl" scale="0.001 0.001 0.001"/>
    </geometry>
    <material name="silver"/>
  </visual>
  <collision>
    <origin xyz="-0.003112 -0.03903 -0.043746" rpy="0 0 0"/>
    <geometry>
      <mesh filename="package://humanoid_urdf_description/meshes/ll5_1.stl" scale="0.001 0.001 0.001"/>
    </geometry>
  </collision>
</link>

<link name="rl5_1">
  <inertial>
    <origin xyz="-0.022668245682832017 -0.019247066655979854 0.012149203935575538" rpy="0 0 0"/>
    <mass value="0.13078226931984768"/>
    <inertia ixx="3.4e-05" iyy="0.000105" izz="9.4e-05" ixy="1e-06" iyz="-0.0" ixz="0.0"/>
  </inertial>
  <visual>
    <origin xyz="-0.003177 0.04297 -0.038546" rpy="0 0 0"/>
    <geometry>
      <mesh filename="package://humanoid_urdf_description/meshes/rl5_1.stl" scale="0.001 0.001 0.001"/>
    </geometry>
    <material name="silver"/>
  </visual>
  <collision>
    <origin xyz="-0.003177 0.04297 -0.038546" rpy="0 0 0"/>
    <geometry>
      <mesh filename="package://humanoid_urdf_description/meshes/rl5_1.stl" scale="0.001 0.001 0.001"/>
    </geometry>
  </collision>
</link>

<link name="rshd_2xl_1">
  <inertial>
    <origin xyz="0.018505184628533105 -0.004985074770461395 0.01229030110927748" rpy="0 0 0"/>
    <mass value="0.08457536214369274"/>
    <inertia ixx="2.8e-05" iyy="2.3e-05" izz="2.1e-05" ixy="-1e-06" iyz="1e-06" ixz="0.0"/>
  </inertial>
  <visual>
    <origin xyz="7.6e-05 0.111004 -0.381916" rpy="0 0 0"/>
    <geometry>
      <mesh filename="package://humanoid_urdf_description/meshes/rshd_2xl_1.stl" scale="0.001 0.001 0.001"/>
    </geometry>
    <material name="silver"/>
  </visual>
  <collision>
    <origin xyz="7.6e-05 0.111004 -0.381916" rpy="0 0 0"/>
    <geometry>
      <mesh filename="package://humanoid_urdf_description/meshes/rshd_2xl_1.stl" scale="0.001 0.001 0.001"/>
    </geometry>
  </collision>
</link>

<joint name="lgripper_joint" type="revolute">
  <origin xyz="0.019 0.0397 0.0" rpy="0 0 0"/>
  <parent link="lgripper_1"/>
  <child link="lgrip_gear_1"/>
  <axis xyz="-0.0 1.0 0.0"/>
  <dynamics damping="10.0" friction="0.0"/>  <!-- 이 줄 추가 -->
  <limit upper="0.8727" lower="-5.2360" effort="100" velocity="100"/>
</joint>

<!-- 슬레이브 1: fin1 -->
<joint name="lgrip_fin1_slider" type="prismatic">
  <origin xyz="0.018907 0.0389 0.0192" rpy="0 0 0"/>
  <parent link="lgripper_1"/>
  <child link="lgrip_fin1_1"/>
  <axis xyz="1.0 0.0 0.0"/>
  <dynamics damping="10.0" friction="0.0"/>
  <limit upper="0.007" lower="-0.02" effort="100" velocity="100"/>
  <mimic joint="lgripper_joint" multiplier="0.00869" offset="0.0"/>
</joint>

<!-- 슬레이브 2: fin2 (반대 방향) -->
<joint name="lgrip_fin2_slider" type="prismatic">
  <origin xyz="0.019 0.0389 -0.0192" rpy="0 0 0"/>
  <parent link="lgripper_1"/>
  <child link="lgrip_fin2_1"/>
  <axis xyz="1.0 0.0 0.0"/>
  <dynamics damping="10.0" friction="0.0"/>
  <limit upper="0.02" lower="-0.007" effort="100" velocity="100"/>
  <mimic joint="lgrip_fin1_slider" multiplier="-1.0" offset="0.0"/>
</joint>

<joint name="lshd_yaw_joint" type="revolute">
  <origin xyz="-0.019 0.027 0.0" rpy="0 0 0"/>
  <parent link="lshd_pitch_1"/>
  <child link="lshd_2xl_1"/>
  <axis xyz="1.0 -0.0 0.0"/>
  <dynamics damping="10.0" friction="0.0"/>  <!-- 이 줄 추가 -->
  <limit upper="0.349066" lower="-1.570796" effort="100" velocity="100"/>
</joint>

<joint name="lwrist_pitch_joint" type="revolute">
  <origin xyz="0.0 0.1002 0.045" rpy="0 0 0"/>
  <parent link="lelbow_1"/>
  <child link="lwrist_1"/>
  <axis xyz="0.0 0.0 -1.0"/>
  <dynamics damping="10.0" friction="0.0"/>  <!-- 이 줄 추가 -->
  <limit upper="1.570796" lower="-1.570796" effort="100" velocity="100"/>
</joint>

<joint name="lwrist_yaw_joint" type="revolute">
  <origin xyz="-0.019 0.0 -0.0287" rpy="0 0 0"/>
  <parent link="lwrist_1"/>
  <child link="lgripper_1"/>
  <axis xyz="-1.0 -0.0 -0.0"/>
  <dynamics damping="10.0" friction="0.0"/>  <!-- 이 줄 추가 -->
  <limit upper="0.349066" lower="-0.349066" effort="100" velocity="100"/>
</joint>

<joint name="rwrist_pitch_joint" type="revolute">
  <origin xyz="0.0 -0.1002 0.045" rpy="0 0 0"/>
  <parent link="relbow_1"/>
  <child link="rwrist_1"/>
  <axis xyz="0.0 -0.0 -1.0"/>
  <dynamics damping="10.0" friction="0.0"/>  <!-- 이 줄 추가 -->
  <limit upper="1.570796" lower="-1.570796" effort="100" velocity="100"/>
</joint>

<joint name="rwrist_yaw_joint" type="revolute">
  <origin xyz="0.019 0.0 -0.0287" rpy="0 0 0"/>
  <parent link="rwrist_1"/>
  <child link="rgripper_1"/>
  <axis xyz="1.0 0.0 0.0"/>
  <dynamics damping="10.0" friction="0.0"/>  <!-- 이 줄 추가 -->
  <limit upper="0.349066" lower="-0.349066" effort="100" velocity="100"/>
</joint>

<joint name="rgripper_joint" type="revolute">
  <origin xyz="-0.019 -0.0397 0.0" rpy="0 0 0"/>
  <parent link="rgripper_1"/>
  <child link="rgrip_gear_1"/>
  <axis xyz="-0.0 1.0 0.0"/>
  <dynamics damping="10.0" friction="0.0"/>  <!-- 이 줄 추가 -->
  <limit upper="0.8727" lower="-5.2360" effort="100" velocity="100"/>
</joint>

<joint name="rgrip_fin1_slider" type="prismatic">
  <origin xyz="-0.019 -0.0389 -0.0192" rpy="0 0 0"/>
  <parent link="rgripper_1"/>
  <child link="rgrip_fin1_1"/>
  <axis xyz="1.0 0.0 0.0"/>
  <dynamics damping="10.0" friction="0.0"/>  <!-- 이 줄 추가 -->
  <limit upper="0.007" lower="-0.02" effort="100" velocity="100"/>
  <mimic joint="rgripper_joint" multiplier="0.00869" offset="0.0"/>
</joint>

<joint name="rgrip_fin2_slider" type="prismatic">
  <origin xyz="-0.019093 -0.0389 0.0192" rpy="0 0 0"/>
  <parent link="rgripper_1"/>
  <child link="rgrip_fin2_1"/>
  <axis xyz="1.0 0.0 0.0"/>
  <dynamics damping="10.0" friction="0.0"/>  <!-- 이 줄 추가 -->
  <limit upper="0.02" lower="-0.007" effort="100" velocity="100"/>
  <mimic joint="rgrip_fin1_slider" multiplier="-1.0" offset="0.0"/>
</joint>

<joint name="rshd_pitch_joint" type="revolute">
  <origin xyz="0.018924 -0.084004 0.381916" rpy="0 0 0"/>
  <parent link="base_link"/>
  <child link="rshd_pitch_1"/>
  <axis xyz="-0.0 -1.0 0.0"/>
  <dynamics damping="10.0" friction="0.0"/>  <!-- 이 줄 추가 -->
  <limit upper="3.141592" lower="-3.141592" effort="100" velocity="100"/>
</joint>

<joint name="lshd_pitch_joint" type="revolute">
  <origin xyz="0.018924 0.080206 0.381916" rpy="0 0 0"/>
  <parent link="base_link"/>
  <child link="lshd_pitch_1"/>
  <axis xyz="0.0 1.0 -0.0"/>
  <dynamics damping="10.0" friction="0.0"/>  <!-- 이 줄 추가 -->
  <limit upper="3.141592" lower="-3.141592" effort="100" velocity="100"/>
</joint>

<joint name="neck_roll_joint" type="revolute">
  <origin xyz="0.009136 -0.002011 0.419533" rpy="0 0 0"/>
  <parent link="base_link"/>
  <child link="neck_1"/>
  <axis xyz="-0.0 -0.0 -1.0"/>
  <dynamics damping="10.0" friction="0.0"/>  <!-- 이 줄 추가 -->
  <limit upper="1.570796" lower="-1.570796" effort="100" velocity="100"/>
</joint>

<joint name="neck_pitch_joint" type="revolute">
  <origin xyz="-9.1e-05 -0.014046 0.018566" rpy="0 0 0"/>
  <parent link="neck_1"/>
  <child link="head_1"/>
  <axis xyz="0.0 -1.0 0.0"/>
  <dynamics damping="10.0" friction="0.0"/>  <!-- 이 줄 추가 -->
  <limit upper="1.570796" lower="-1.570796" effort="100" velocity="100"/>
</joint>

<joint name="lbase_joint" type="revolute">
  <origin xyz="0.001007 0.05803 0.258033" rpy="0 0 0"/>
  <parent link="base_link"/>
  <child link="ll1_1"/>
  <axis xyz="0.0 -0.0 -1.0"/>
  <dynamics damping="10.0" friction="0.0"/>  <!-- 이 줄 추가 -->
  <limit upper="0.0" lower="-1.570796" effort="100" velocity="100"/>
</joint>

<joint name="ll1_joint" type="revolute">
  <origin xyz="0.02042 0.0 -0.0345" rpy="0 0 0"/>
  <parent link="ll1_1"/>
  <child link="ll2_1"/>
  <axis xyz="-1.0 -0.0 -0.0"/>
  <dynamics damping="10.0" friction="0.0"/>  <!-- 이 줄 추가 -->
  <limit upper="0.349066" lower="-1.570796" effort="100" velocity="100"/>
</joint>

<joint name="rbase_joint" type="revolute">
  <origin xyz="0.001007 -0.06197 0.258033" rpy="0 0 0"/>
  <parent link="base_link"/>
  <child link="rl1_1"/>
  <axis xyz="0.0 -0.0 -1.0"/>
  <dynamics damping="10.0" friction="0.0"/>  <!-- 이 줄 추가 -->
  <limit upper="1.570796" lower="0.0" effort="100" velocity="100"/>
</joint>

<joint name="rl3_joint" type="revolute">
  <origin xyz="0.0 0.0 -0.092493" rpy="0 0 0"/>
  <parent link="rl3_1"/>
  <child link="rl4_1"/>
  <axis xyz="-0.0 1.0 -0.0"/>
  <dynamics damping="10.0" friction="0.0"/>  <!-- 이 줄 추가 -->
  <limit upper="1.570796" lower="0.0" effort="100" velocity="100"/>
</joint>

<joint name="rl5_joint" type="revolute">
  <origin xyz="-0.029239 -0.019 0.0" rpy="0 0 0"/>
  <parent link="rl5_1"/>
  <child link="rl6_1"/>
  <axis xyz="1.0 0.0 0.0"/>
  <dynamics damping="10.0" friction="0.0"/>  <!-- 이 줄 추가 -->
  <limit upper="0.349066" lower="-1.570796" effort="100" velocity="100"/>
</joint>

<joint name="ll2_joint" type="revolute">
  <origin xyz="-0.01825 -0.019 -8e-06" rpy="0 0 0"/>
  <parent link="ll2_1"/>
  <child link="ll3_1"/>
  <axis xyz="0.0 -1.0 0.0"/>
  <dynamics damping="10.0" friction="0.0"/>  <!-- 이 줄 추가 -->
  <limit upper="1.570796" lower="-0.349066" effort="100" velocity="100"/>
</joint>

<joint name="ll3_joint" type="revolute">
  <origin xyz="-6.5e-05 0.0 -0.087294" rpy="0 0 0"/>
  <parent link="ll3_1"/>
  <child link="ll4_1"/>
  <axis xyz="0.0 -1.0 0.0"/>
  <dynamics damping="10.0" friction="0.0"/>  <!-- 이 줄 추가 -->
  <limit upper="0.0" lower="-1.570796" effort="100" velocity="100"/>
</joint>

<joint name="ll5_joint" type="revolute">
  <origin xyz="-0.029239 0.019 0.0" rpy="0 0 0"/>
  <parent link="ll5_1"/>
  <child link="ll6_1"/>
  <axis xyz="1.0 0.0 0.0"/>
  <dynamics damping="10.0" friction="0.0"/>  <!-- 이 줄 추가 -->
  <limit upper="1.570796" lower="-0.349066" effort="100" velocity="100"/>
</joint>

<joint name="rl1_joint" type="revolute">
  <origin xyz="0.02042 0.0 -0.0345" rpy="0 0 0"/>
  <parent link="rl1_1"/>
  <child link="rl2_1"/>
  <axis xyz="-1.0 -0.0 -0.0"/>
  <dynamics damping="10.0" friction="0.0"/>  <!-- 이 줄 추가 -->
  <limit upper="1.570796" lower="-0.349066" effort="100" velocity="100"/>
</joint>

<joint name="rl2_joint" type="revolute">
  <origin xyz="-0.01825 0.019 -8e-06" rpy="0 0 0"/>
  <parent link="rl2_1"/>
  <child link="rl3_1"/>
  <axis xyz="-0.0 1.0 -0.0"/>
  <dynamics damping="10.0" friction="0.0"/>  <!-- 이 줄 추가 -->
  <limit upper="0.349066" lower="-1.570796" effort="100" velocity="100"/>
</joint>

<joint name="lshd_roll_joint" type="revolute">
  <origin xyz="0.019 0.026 0.0" rpy="0 0 0"/>
  <parent link="lshd_2xl_1"/>
  <child link="lshd_yaw_1"/>
  <axis xyz="-0.0 1.0 0.0"/>
  <dynamics damping="10.0" friction="0.0"/>  <!-- 이 줄 추가 -->
  <limit upper="1.570796" lower="-1.570796" effort="100" velocity="100"/>
</joint>

<joint name="lelbow_joint" type="revolute">
  <origin xyz="0.0 0.0437 -0.019" rpy="0 0 0"/>
  <parent link="lshd_yaw_1"/>
  <child link="lelbow_1"/>
  <axis xyz="0.0 0.0 -1.0"/>
  <dynamics damping="10.0" friction="0.0"/>  <!-- 이 줄 추가 -->
  <limit upper="2.094395" lower="-2.094395" effort="100" velocity="100"/>
</joint>

<joint name="rshd_roll_joint" type="revolute">
  <origin xyz="0.018 -0.026 0.0" rpy="0 0 0"/>
  <parent link="rshd_2xl_1"/>
  <child link="rshd_yaw_1"/>
  <axis xyz="0.0 -1.0 0.0"/>
  <dynamics damping="10.0" friction="0.0"/>  <!-- 이 줄 추가 -->
  <limit upper="1.570796" lower="-1.570796" effort="100" velocity="100"/>
</joint>

<joint name="relbow_joint" type="revolute">
  <origin xyz="0.0 -0.0437 -0.019" rpy="0 0 0"/>
  <parent link="rshd_yaw_1"/>
  <child link="relbow_1"/>
  <axis xyz="-0.0 -0.0 -1.0"/>
  <dynamics damping="10.0" friction="0.0"/>  <!-- 이 줄 추가 -->
  <limit upper="2.094395" lower="-2.094395" effort="100" velocity="100"/>
</joint>

<joint name="ll4_joint" type="revolute">
  <origin xyz="0.0 0.0 -0.092485" rpy="0 0 0"/>
  <parent link="ll4_1"/>
  <child link="ll5_1"/>
  <axis xyz="0.0 1.0 -0.0"/>
  <dynamics damping="10.0" friction="0.0"/>  <!-- 이 줄 추가 -->
  <limit upper="0.349066" lower="-1.570796" effort="100" velocity="100"/>
</joint>

<joint name="rl4_joint" type="revolute">
  <origin xyz="0.0 0.0 -0.092486" rpy="0 0 0"/>
  <parent link="rl4_1"/>
  <child link="rl5_1"/>
  <axis xyz="0.0 -1.0 0.0"/>
  <dynamics damping="10.0" friction="0.0"/>  <!-- 이 줄 추가 -->
  <limit upper="1.570796" lower="-0.349066" effort="100" velocity="100"/>
</joint>

<joint name="rshd_yaw_joint" type="revolute">
  <origin xyz="-0.019 -0.027 0.0" rpy="0 0 0"/>
  <parent link="rshd_pitch_1"/>
  <child link="rshd_2xl_1"/>
  <axis xyz="1.0 0.0 -0.0"/>
  <dynamics damping="10.0" friction="0.0"/>  <!-- 이 줄 추가 -->
  <limit upper="1.570796" lower="-0.349066" effort="100" velocity="100"/>
</joint>

</robot>
